Workbook

Sheet Janeiro 2018
A1: ACIONAMENTO - JANEIRO
A2: Seguradora/Regulador | B2: AIG | C2: ALLIANZ | D2: ARGO | E2: AXA | F2: BERKLEY | G2: CHUBB | H2: FAIRFAX | I2: FATOR | J2: LIBERTY | K2: QBE | L2: SULAMÉRICA | M2: SURA | N2: Total
A3: Ana Herrera | D3: 3 | N3: =SUM(B3:M3) -> 3 | O3: =N3/$N$22 -> 0.05
A4: Antonio | K4: 2 | N4: =SUM(B4:M4) -> 2 | O4: =N4/$N$22 -> 0.033333333
A5: Carlos | B5: 1 | D5: 2 | N5: =SUM(B5:M5) -> 3 | O5: =N5/$N$22 -> 0.05
A6: Caroline Motta | B6: 1 | D6: 2 | N6: =SUM(B6:M6) -> 3 | O6: =N6/$N$22 -> 0.05
A7: Diego | N7: =SUM(B7:M7) -> 0 | O7: =N7/$N$22 -> 0
A8: Emílio | D8: 4 | N8: =SUM(B8:M8) -> 4 | O8: =N8/$N$22 -> 0.066666667
A9: Everton | D9: 3 | N9: =SUM(B9:M9) -> 3 | O9: =N9/$N$22 -> 0.05
A10: Fabielle | D10: 3 | F10: 2 | N10: =SUM(B10:M10) -> 5 | O10: =N10/$N$22 -> 0.083333333
A11: Fernanda | D11: 4 | N11: =SUM(B11:M11) -> 4 | O11: =N11/$N$22 -> 0.066666667
A12: Jéssica Carvalho | D12: 6 | N12: =SUM(B12:M12) -> 6 | O12: =N12/$N$22 -> 0.1
A13: Jéssica Rosa | D13: 1 | N13: =SUM(B13:M13) -> 1 | O13: =N13/$N$22 -> 0.016666667
A14: João | D14: 3 | N14: =SUM(B14:M14) -> 3 | O14: =N14/$N$22 -> 0.05
A15: Karina | D15: 3 | N15: =SUM(B15:M15) -> 3 | O15: =N15/$N$22 -> 0.05
A16: Karisa | D16: 4 | E16: 1 | N16: =SUM(B16:M16) -> 5 | O16: =N16/$N$22 -> 0.083333333
A17: Maria Beatriz | B17: 2 | D17: 1 | N17: =SUM(B17:M17) -> 3 | O17: =N17/$N$22 -> 0.05
A18: Pâmela | D18: 3 | N18: =SUM(B18:M18) -> 3 | O18: =N18/$N$22 -> 0.05
A19: Renata | B19: 1 | D19: 1 | J19: 4 | N19: =SUM(B19:M19) -> 6 | O19: =N19/$N$22 -> 0.1
A20: Seidy | B20: 1 | D20: 2 | N20: =SUM(B20:M20) -> 3 | O20: =N20/$N$22 -> 0.05
A21: Teresa | N21: =SUM(B21:M21) -> 0 | O21: =N21/$N$22 -> 0
A22: Total | B22: =SUM(B3:B21) -> 6 | C22: =SUM(C3:C21) -> 0 | D22: =SUM(D3:D21) -> 45 | E22: =SUM(E3:E21) -> 1 | F22: =SUM(F3:F21) -> 2 | G22: =SUM(G3:G21) -> 0 | H22: =SUM(H3:H21) -> 0 | I22: =SUM(I3:I21) -> 0 | ... M22: =SUM(M3:M21) -> 0 | N22: =SUM(N2:N20) -> 60 | O22: =SUM(O2:O20) -> 1
A24: Produto | B24: Contador | C24: Corretor | D24: Médico | E24: Dentista | F24: RCPM | G24: Advogado | H24: Despachante | I24: Posto | J24: Cartório | K24: D & O | L24: Turismo | M24: Diversos
A25: Total | B25: =B48 -> 13 | C25: =C48 -> 2 | D25: =D48 -> 18 | E25: =E48 -> 1 | F25: =F48 -> 10 | G25: =G48 -> 1 | H25: =H48 -> 0 | I25: =I48 -> 0 | ... M25: =M48 -> 12
A26: Estado
A27: AL
A28: BA | C28: 1 | M28: 1
A29: CE
A30: DF | B30: 1 | M30: 1
A31: ES
A32: GO | F32: 4
A33: MA
A34: MG | B34: 3 | D34: 1 | J34: 1 | M34: 3
A35: MS | E35: 1
A36: MT
A37: PA
A38: PB | F38: 2
A39: PE
A40: PR | D40: 1 | F40: 1
A41: RJ | D41: 7 | F41: 1
...

Sheet Fevereiro 2018
A1: ACIONAMENTO - FEVEREIRO
A2: Seguradora/Regulador | B2: AIG | C2: ALLIANZ | D2: ARGO | E2: AXA | F2: BERKLEY | G2: CHUBB | H2: FAIRFAX | I2: FATOR | J2: LIBERTY | K2: QBE | L2: SULAMÉRICA | M2: SURA | N2: Total
A3: Ana Herrera | D3: 3 | N3: =SUM(B3:M3) -> 3 | O3: =N3/$N$20 -> 0.050847458
A4: Antonio | K4: 1 | N4: =SUM(B4:M4) -> 1 | O4: =N4/$N$20 -> 0.016949153
A5: Carlos | B5: 1 | D5: 2 | F5: 7 | N5: =SUM(B5:M5) -> 10 | O5: =N5/$N$20 -> 0.16949153
A6: Caroline Motta | D6: 3 | N6: =SUM(B6:M6) -> 3 | O6: =N6/$N$20 -> 0.050847458
A7: Emílio | D7: 3 | N7: =SUM(B7:M7) -> 3 | O7: =N7/$N$20 -> 0.050847458
A8: Everton | D8: 5 | N8: =SUM(B8:M8) -> 5 | O8: =N8/$N$20 -> 0.084745763
A9: Fabielle | D9: 2 | N9: =SUM(B9:M9) -> 2 | O9: =N9/$N$20 -> 0.033898305
A10: Fernanda | D10: 3 | N10: =SUM(B10:M10) -> 3 | O10: =N10/$N$20 -> 0.050847458
A11: Jéssica Carvalho | B11: 1 | D11: 2 | N11: =SUM(B11:M11) -> 3 | O11: =N11/$N$20 -> 0.050847458
A12: Jéssica Rosa | B12: 1 | D12: 2 | E12: 1 | N12: =SUM(B12:M12) -> 4 | O12: =N12/$N$20 -> 0.06779661
A13: João | D13: 2 | I13: 1 | N13: =SUM(B13:M13) -> 3 | O13: =N13/$N$20 -> 0.050847458
A14: Karina | B14: 1 | D14: 2 | N14: =SUM(B14:M14) -> 3 | O14: =N14/$N$20 -> 0.050847458
A15: Karisa | D15: 4 | N15: =SUM(B15:M15) -> 4 | O15: =N15/$N$20 -> 0.06779661
A16: Maria Beatriz | B16: 1 | D16: 2 | N16: =SUM(B16:M16) -> 3 | O16: =N16/$N$20 -> 0.050847458
A17: Pâmela | B17: 1 | D17: 1 | E17: 1 | N17: =SUM(B17:M17) -> 3 | O17: =N17/$N$20 -> 0.050847458
A18: Renata | D18: 3 | N18: =SUM(B18:M18) -> 3 | O18: =N18/$N$20 -> 0.050847458
A19: Seidy | D19: 3 | N19: =SUM(B19:M19) -> 3 | O19: =N19/$N$20 -> 0.050847458
A20: Total | B20: =SUM(B3:B19) -> 6 | C20: =SUM(C3:C19) -> 0 | D20: =SUM(D3:D19) -> 42 | E20: =SUM(E3:E19) -> 2 | F20: =SUM(F3:F19) -> 7 | G20: =SUM(G3:G19) -> 0 | H20: =SUM(H3:H19) -> 0 | I20: =SUM(I3:I19) -> 1 | ... M20: =SUM(M3:M19) -> 0 | N20: =SUM(N2:N19) -> 59 | O20: =SUM(O2:O19) -> 1
A22: Produto | B22: Contador | C22: Corretor | D22: Médico | E22: Dentista | F22: RCPM | G22: Advogado | H22: Despachante | I22: Posto | J22: Cartório | K22: D & O | L22: Turismo | M22: Diversos
A23: Total | B23: =B46 -> 18 | C23: =C46 -> 5 | D23: =D46 -> 5 | E23: =E46 -> 4 | F23: =F46 -> 14 | G23: =G46 -> 1 | H23: =H46 -> 1 | I23: =I46 -> 0 | ... M23: =M46 -> 8
A24: Estado
A25: AL | D25: 1
A26: BA
A27: CE
A28: DF | E28: 1
A29: ES | B29: 1 | F29: 4
A30: GO
A31: MA | F31: 2
A32: MG | B32: 7 | D32: 3 | E32: 1 | F32: 1
A33: MS
A34: MT
A35: PA | F35: 2
A36: PB | M36: 1
A37: PE | E37: 1 | F37: 2 | M37: 1
A38: PR | B38: 2 | D38: 1 | F38: 2
A39: RJ | F39: 1
A40: RN
A41: RO | B41: 1 | M41: 1
...

Sheet Março 2018
A1: ACIONAMENTO - MARÇO
A2: Seguradora/Regulador | B2: AIG | C2: ALLIANZ | D2: ARGO | E2: AXA | F2: BERKLEY | G2: CHUBB | H2: FAIRFAX | I2: FATOR | J2: LIBERTY | K2: QBE | L2: SULAMÉRICA | M2: SURA | N2: Total
A3: Ana Herrera | D3: 5 | G3: 1 | N3: =SUM(B3:M3) -> 6 | O3: =N3/$N$20 -> 0.068181818
A4: Antonio | K4: 4 | N4: =SUM(B4:M4) -> 4 | O4: =N4/$N$20 -> 0.045454545
A5: Carlos | B5: 2 | D5: 4 | N5: =SUM(B5:M5) -> 6 | O5: =N5/$N$20 -> 0.068181818
A6: Caroline Motta | B6: 4 | D6: 3 | N6: =SUM(B6:M6) -> 7 | O6: =N6/$N$20 -> 0.079545455
A7: Emílio | D7: 2 | N7: =SUM(B7:M7) -> 2 | O7: =N7/$N$20 -> 0.022727273
A8: Everton | D8: 7 | N8: =SUM(B8:M8) -> 7 | O8: =N8/$N$20 -> 0.079545455
A9: Fabielle | B9: 1 | D9: 4 | N9: =SUM(B9:M9) -> 5 | O9: =N9/$N$20 -> 0.056818182
A10: Fernanda | D10: 7 | N10: =SUM(B10:M10) -> 7 | O10: =N10/$N$20 -> 0.079545455
A11: Jéssica Carvalho | B11: 2 | D11: 5 | N11: =SUM(B11:M11) -> 7 | O11: =N11/$N$20 -> 0.079545455
A12: Jéssica Rosa | B12: 1 | D12: 1 | N12: =SUM(B12:M12) -> 2 | O12: =N12/$N$20 -> 0.022727273
A13: João | B13: 1 | D13: 7 | N13: =SUM(B13:M13) -> 8 | O13: =N13/$N$20 -> 0.090909091
A14: Karina | B14: 1 | D14: 5 | N14: =SUM(B14:M14) -> 6 | O14: =N14/$N$20 -> 0.068181818
A15: Karisa | D15: 2 | E15: 1 | N15: =SUM(B15:M15) -> 3 | O15: =N15/$N$20 -> 0.034090909
A16: Maria Beatriz | B16: 2 | D16: 4 | N16: =SUM(B16:M16) -> 6 | O16: =N16/$N$20 -> 0.068181818
A17: Pâmela | D17: 3 | N17: =SUM(B17:M17) -> 3 | O17: =N17/$N$20 -> 0.034090909
A18: Renata | D18: 2 | N18: =SUM(B18:M18) -> 2 | O18: =N18/$N$20 -> 0.022727273
A19: Seidy | B19: 3 | D19: 4 | N19: =SUM(B19:M19) -> 7 | O19: =N19/$N$20 -> 0.079545455
A20: Total | B20: =SUM(B3:B19) -> 17 | C20: =SUM(C3:C19) -> 0 | D20: =SUM(D3:D19) -> 65 | E20: =SUM(E3:E19) -> 1 | F20: =SUM(F3:F19) -> 0 | G20: =SUM(G3:G19) -> 1 | H20: =SUM(H3:H19) -> 0 | I20: =SUM(I3:I19) -> 0 | ... M20: =SUM(M3:M19) -> 0 | N20: =SUM(N2:N19) -> 88 | O20: =SUM(O2:O19) -> 1
A22: Produto | B22: Contador | C22: Corretor | D22: Médico | E22: Dentista | F22: RCPM | G22: Advogado | H22: Despachante | I22: Posto | J22: Cartório | K22: D & O | L22: Turismo | M22: Diversos
A23: Total | B23: =B46 -> 19 | C23: =C46 -> 10 | D23: =D46 -> 11 | E23: =E46 -> 6 | F23: =F46 -> 21 | G23: =G46 -> 4 | H23: =H46 -> 2 | I23: =I46 -> 2 | ... M23: =M46 -> 5
A24: Estado
A25: AL
A26: BA | D26: 1
A27: CE | F27: 1 | J27: 1
A28: DF
A29: ES | C29: 2
A30: GO | B30: 1 | F30: 2 | H30: 1
A31: MA | F31: 1
A32: MG | B32: 2 | C32: 2 | F32: 3 | M32: 1
A33: MS | B33: 1 | F33: 4
A34: MT | F34: 1
A35: PA | F35: 1
A36: PB
A37: PE | B37: 1
A38: PR | L38: 1
A39: RJ | B39: 3 | D39: 2 | F39: 2 | L39: 1
A40: RN | D40: 1 | F40: 2
A41: RO | E41: 1
...

Sheet Abril 2018
A1: ACIONAMENTO - ABRIL
A2: Seguradora/Regulador | B2: AIG | C2: ALLIANZ | D2: ARGO | E2: AXA | F2: BERKLEY | G2: CHUBB | H2: FAIRFAX | I2: FATOR | J2: LIBERTY | K2: QBE | L2: SULAMÉRICA | M2: SURA | N2: TOKIO | O2: SWISS | P2: Total
A3: Ana Herrera | B3: 2 | D3: 4 | J3: 1 | K3: 1 | P3: =SUM(B3:O3) -> 8 | Q3: =P3/$P$15 -> 0.094117647
A4: Carlos | B4: 1 | D4: 4 | P4: =SUM(B4:O4) -> 5 | Q4: =P4/$P$15 -> 0.058823529
A5: Caroline Motta | B5: 1 | D5: 8 | P5: =SUM(B5:O5) -> 9 | Q5: =P5/$P$15 -> 0.10588235
A6: Diego | E6: 1 | P6: =SUM(B6:O6) -> 1 | Q6: =P6/$P$15 -> 0.011764706
A7: Everton | B7: 2 | D7: 6 | P7: =SUM(B7:O7) -> 8 | Q7: =P7/$P$15 -> 0.094117647
A8: Fernanda | D8: 4 | O8: 1 | P8: =SUM(B8:O8) -> 5 | Q8: =P8/$P$15 -> 0.058823529
A9: Jéssica Carvalho | B9: 2 | D9: 7 | P9: =SUM(B9:O9) -> 9 | Q9: =P9/$P$15 -> 0.10588235
A10: João | D10: 6 | J10: 1 | P10: =SUM(B10:O10) -> 7 | Q10: =P10/$P$15 -> 0.082352941
A11: Karina | B11: 2 | D11: 6 | P11: =SUM(B11:O11) -> 8 | Q11: =P11/$P$15 -> 0.094117647
A12: Maria Beatriz | B12: 1 | D12: 2 | E12: 1 | J12: 1 | P12: =SUM(B12:O12) -> 5 | Q12: =P12/$P$15 -> 0.058823529
A13: Renata | B13: 2 | D13: 6 | P13: =SUM(B13:O13) -> 8 | Q13: =P13/$P$15 -> 0.094117647
A14: Seidy | D14: 11 | J14: 1 | P14: =SUM(B14:O14) -> 12 | Q14: =P14/$P$15 -> 0.14117647
A15: Total | B15: =SUM(B3:B14) -> 13 | C15: =SUM(C3:C14) -> 0 | D15: =SUM(D3:D14) -> 64 | E15: =SUM(E3:E14) -> 2 | F15: =SUM(F3:F14) -> 0 | G15: =SUM(G3:G14) -> 0 | H15: =SUM(H3:H14) -> 0 | I15: =SUM(I3:I14) -> 0 | ... O15: =SUM(O3:O14) -> 1 | P15: =SUM(P2:P14) -> 85 | Q15: =SUM(Q2:Q14) -> 1
A18: Produto | B18: Contador | C18: Corretor | D18: Médico | E18: Dentista | F18: RCPM | G18: Advogado | H18: Despachante | I18: Posto | J18: Cartório | K18: D & O | L18: Turismo | M18: Diversos
A19: Total | B19: =B48 -> 14 | C19: =C48 -> 17 | D19: =D48 -> 19 | E19: =E48 -> 5 | F19: =F48 -> 14 | G19: =G48 -> 2 | H19: =H48 -> 1 | J19: =J48 -> 5 | L19: =L48 -> 1 | M19: =M48 -> 7
A20: Estado
A21: AC
A22: AL
A23: AM
A24: AP
A25: BA | D25: 2
A26: CE | F26: 1 | J26: 1 | L26: 1
A27: DF | B27: 1 | E27: 1
A28: ES | B28: 1 | G28: 1
A29: GO | F29: 2 | J29: 1 | M29: 1
A30: MA
A31: MG | B31: 1 | C31: 2 | F31: 3 | J31: 1 | M31: 1
A32: MS | D32: 1 | F32: 1 | M32: 1
A33: MT
A34: PA
A35: PB
A36: PE
A37: PI | F37: 1
A38: PR | C38: 2 | F38: 1 | J38: 1
A39: RJ | C39: 1 | D39: 10 | F39: 1
A40: RN
A41: RO | E41: 1
A42: RR
...

Sheet Maio 2018
A1: ACIONAMENTO - MAIO
A2: Regulador/Seguradora | B2: ARGO | C2: AIG | D2: LIBERTY | E2: AXA | F2: QBE | G2: TÓKIO | O2: Total
A3: Ana Herrera | B3: 6 | F3: 1 | O3: =SUM(B3:N3) -> 7 | P3: =O3/$O$15 -> 0.072164948
A4: Carlos Edson | B4: 8 | F4: 1 | O4: =SUM(B4:N4) -> 9 | P4: =O4/$O$15 -> 0.092783505
A5: Caroline Motta | B5: 7 | C5: 1 | E5: 1 | O5: =SUM(B5:N5) -> 9 | P5: =O5/$O$15 -> 0.092783505
A6: Everton Gustavo | B6: 8 | E6: 1 | O6: =SUM(B6:N6) -> 9 | P6: =O6/$O$15 -> 0.092783505
A7: Fernanda Sanches | B7: 4 | C7: 3 | E7: 1 | G7: 1 | O7: =SUM(B7:N7) -> 9 | P7: =O7/$O$15 -> 0.092783505
A8: João Vitor | B8: 7 | C8: 1 | E8: 1 | O8: =SUM(B8:N8) -> 9 | P8: =O8/$O$15 -> 0.092783505
A9: Karisa Virgílio | B9: 6 | C9: 1 | O9: =SUM(B9:N9) -> 7 | P9: =O9/$O$15 -> 0.072164948
A10: Jéssica Carvalho | B10: 9 | C10: 2 | O10: =SUM(B10:N10) -> 11 | P10: =O10/$O$15 -> 0.11340206
A11: Seidy | B11: 7 | C11: 1 | O11: =SUM(B11:N11) -> 8 | P11: =O11/$O$15 -> 0.082474227
A12: Maria Beatriz | B12: 6 | C12: 2 | O12: =SUM(B12:N12) -> 8 | P12: =O12/$O$15 -> 0.082474227
A13: Karina | B13: 6 | C13: 2 | O13: =SUM(B13:N13) -> 8 | P13: =O13/$O$15 -> 0.082474227
A14: Jéssica Rosa | B14: 2 | C14: 1 | O14: =SUM(B14:N14) -> 3 | P14: =O14/$O$15 -> 0.030927835
A15: Total | B15: =SUM(B3:B14) -> 76 | C15: =SUM(C3:C14) -> 14 | D15: =SUM(D3:D13) -> 0 | E15: =SUM(E3:E13) -> 4 | F15: =SUM(F3:F13) -> 2 | G15: =SUM(G3:G13) -> 1 | H15: =SUM(H3:H13) -> 0 | I15: =SUM(I3:I13) -> 0 | J15: =SUM(J3:J13) -> 0 | K15: =SUM(K3:K13) -> 0 | ... N15: =SUM(N3:N13) -> 0 | O15: =SUM(O2:O14) -> 97 | P15: =SUM(P2:P13) -> 0.96907216
A18: Produto | B18: Contador | C18: Corretor | D18: Médico | E18: Dentista | F18: RCPM | G18: Advogado | H18: Despachante | I18: Posto | J18: Cartório | K18: D & O | L18: Turismo | M18: Diversos
A19: Total | B19: =B48 -> 18 | C19: =C48 -> 7 | D19: =D48 -> 18 | E19: =E48 -> 3 | F19: =F48 -> 25 | G19: =G48 -> 3 | H19: =H48 -> 2 | I19: =I48 -> 2 | ... M19: =M48 -> 12
A20: Estado
A21: AC
A22: AL
A23: AM
A24: AP
A25: BA | F25: 1
A26: CE | F26: 4 | L26: 1
A27: DF | C27: 1 | M27: 1
A28: ES | B28: 1 | L28: 2 | M28: 1
A29: GO | D29: 1 | F29: 3 | M29: 1
A30: MA | F30: 2
A31: MG | B31: 5 | C31: 1 | F31: 2 | M31: 1
A32: MS | F32: 1 | M32: 1
A33: MT | B33: 1 | F33: 1
A34: PA
A35: PB
A36: PE
A37: PI
A38: PR | B38: 1 | F38: 4 | M38: 1
A39: RJ | B39: 1 | D39: 6 | K39: 2 | L39: 1 | M39: 3
A40: RN | F40: 2
A41: RO | D41: 1
A42: RR | F42: 1
...

Sheet Junho 2018
A1: ACIONAMENTO - JUNHO
A2: Regulador/Seguradora | B2: Argo | C2: AIG | D2: AXA | E2: CHUBB | O2: Total
A3: Seidy | B3: 4 | C3: 2 | O3: =B3+C3+D3+E3+F3+G3+H3+I3+J3+K3+L3+M3+N3 -> 6 | P3: =O3/$O$17 -> 0.073170732
A4: Maria Beatriz | B4: 4 | C4: 1 | D4: 2 | O4: =B4+C4+D4+E4+F4+G4+H4+I4+J4+K4+L4+M4+N4 -> 7 | P4: =O4/$O$17 -> 0.085365854
A5: Karina | B5: 5 | C5: 2 | O5: =B5+C5+D5+E5+F5+G5+H5+I5+J5+K5+L5+M5+N5 -> 7 | P5: =O5/$O$17 -> 0.085365854
A6: Ana Herrera | B6: 4 | C6: 2 | E6: 1 | O6: =B6+C6+D6+E6+F6+G6+H6+I6+J6+K6+L6+M6+N6 -> 7 | P6: =O6/$O$17 -> 0.085365854
A7: Carlos | B7: 7 | O7: =B7+C7+D7+E7+F7+G7+H7+I7+J7+K7+L7+M7+N7 -> 7 | P7: =O7/$O$17 -> 0.085365854
A8: Caroline | B8: 7 | O8: =B8+C8+D8+E8+F8+G8+H8+I8+J8+K8+L8+M8+N8 -> 7 | P8: =O8/$O$17 -> 0.085365854
A9: Everton | B9: 6 | C9: 1 | O9: =B9+C9+D9+E9+F9+G9+H9+I9+J9+K9+L9+M9+N9 -> 7 | P9: =O9/$O$17 -> 0.085365854
A10: Karisa | B10: 7 | O10: =B10+C10+D10+E10+F10+G10+H10+I10+J10+K10+L10+M10+N10 -> 7 | P10: =O10/$O$17 -> 0.085365854
A11: Jéssica Rosa | B11: 6 | O11: =B11+C11+D11+E11+F11+G11+H11+I11+J11+K11+L11+M11+N11 -> 6 | P11: =O11/$O$17 -> 0.073170732
A12: João | B12: 5 | C12: 1 | O12: =B12+C12+D12+E12+F12+G12+H12+I12+J12+K12+L12+M12+N12 -> 6 | P12: =O12/$O$17 -> 0.073170732
A13: Fernanda | B13: 3 | C13: 2 | D13: 1 | O13: =B13+C13+D13+E13+F13+G13+H13+I13+J13+K13+L13+M13+N13 -> 6 | P13: =O13/$O$17 -> 0.073170732
A14: Jéssica Carvalho | B14: 6 | O14: =B14+C14+D14+E14+F14+G14+H14+I14+J14+K14+L14+M14+N14 -> 6 | P14: =O14/$O$17 -> 0.073170732
A15: Teresa | B15: 2 | O15: =B15+C15+D15+E15+F15+G15+H15+I15+J15+K15+L15+M15+N15 -> 2 | P15: =O15/$O$17 -> 0.024390244
A16: Diego | C16: 1 | O16: =B16+C16+D16+E16+F16+G16+H16+I16+J16+K16+L16+M16+N16 -> 1 | P16: =O16/$O$17 -> 0.012195122
A17: Total | B17: =SUM(B3:B16) -> 66 | C17: =SUM(C3:C16) -> 12 | D17: =SUM(D3:D14) -> 3 | E17: =SUM(E3:E14) -> 1 | F17: =SUM(F3:F14) -> 0 | G17: =SUM(G3:G14) -> 0 | H17: =SUM(H3:H14) -> 0 | I17: =SUM(I3:I14) -> 0 | J17: =SUM(J3:J14) -> 0 | K17: =SUM(K3:K14) -> 0 | ... N17: =SUM(N3:N14) -> 0 | O17: =SUM(O2:O16) -> 82 | P17: =SUM(P2:P14) -> 0.96341463
A20: Produto | B20: Contador | C20: Corretor | D20: Médico | E20: Dentista | F20: RCPM | G20: Advogado | H20: Despachante | I20: Posto | J20: Cartório | K20: D & O | L20: Turismo | M20: Diversos
A21: Total | B21: =B50 -> 10 | C21: =C50 -> 14 | D21: =D50 -> 14 | E21: =E50 -> 4 | F21: =F50 -> 26 | G21: =G50 -> 2 | H21: =H50 -> 0 | I21: =I50 -> 0 | ... M21: =M50 -> 4
A22: Estado
A23: AC
A24: AL
A25: AM | B25: 1
A26: AP
A27: BA | F27: 1
A28: CE | F28: 2
A29: DF | M29: 1
A30: ES
A31: GO | F31: 4
A32: MA
A33: MG | C33: 1 | F33: 1 | L33: 1
A34: MS | B34: 1 | D34: 2 | F34: 4
A35: MT | C35: 1 | D35: 1
A36: PA
A37: PB | F37: 1
A38: PE | C38: 2 | F38: 1
A39: PI | F39: 1
A40: PR | C40: 1 | E40: 1 | F40: 2 | G40: 1
A41: RJ | C41: 2 | D41: 4 | F41: 3 | M41: 1
A42: RN | F42: 1 | L42: 1
...

Sheet Julho 2018
A1: ACIONAMENTO - JUNHO
A2: Regulador/Seguradora | B2: Argo | C2: AIG | D2: AXA | E2: CHUBB | F2: QBE | G2: FATOR | O2: Total
A3: Jéssica Rosa | B3: 9 | F3: 1 | O3: =B3+C3+D3+E3+F3+G3+H3+I3+J3+K3+L3+M3+N3 -> 10 | P3: =O3/$O$16 -> 0.085470085
A4: Teresa | B4: 8 | O4: =B4+C4+D4+E4+F4+G4+H4+I4+J4+K4+L4+M4+N4 -> 8 | P4: =O4/$O$16 -> 0.068376068
A5: João | B5: 8 | C5: 1 | F5: 1 | G5: 1 | O5: =B5+C5+D5+E5+F5+G5+H5+I5+J5+K5+L5+M5+N5 -> 11 | P5: =O5/$O$16 -> 0.094017094
A6: Fernanda | B6: 7 | C6: 4 | O6: =B6+C6+D6+E6+F6+G6+H6+I6+J6+K6+L6+M6+N6 -> 11 | P6: =O6/$O$16 -> 0.094017094
A7: Jéssica Carvalho | B7: 10 | C7: 2 | O7: =B7+C7+D7+E7+F7+G7+H7+I7+J7+K7+L7+M7+N7 -> 12 | P7: =O7/$O$16 -> 0.1025641
A8: Maria Beatriz | O8: =B8+C8+D8+E8+F8+G8+H8+I8+J8+K8+L8+M8+N8 -> 0 | P8: =O8/$O$16 -> 0
A9: Karina | B9: 11 | O9: =B9+C9+D9+E9+F9+G9+H9+I9+J9+K9+L9+M9+N9 -> 11 | P9: =O9/$O$16 -> 0.094017094
A10: Ana | B10: 4 | E10: 1 | O10: =B10+C10+D10+E10+F10+G10+H10+I10+J10+K10+L10+M10+N10 -> 5 | P10: =O10/$O$16 -> 0.042735043
A11: Carlos | B11: 8 | C11: 3 | O11: =B11+C11+D11+E11+F11+G11+H11+I11+J11+K11+L11+M11+N11 -> 11 | P11: =O11/$O$16 -> 0.094017094
A12: Caroline | B12: 9 | D12: 1 | F12: 1 | O12: =B12+C12+D12+E12+F12+G12+H12+I12+J12+K12+L12+M12+N12 -> 11 | P12: =O12/$O$16 -> 0.094017094
A13: Everton | B13: 8 | C13: 2 | O13: =B13+C13+D13+E13+F13+G13+H13+I13+J13+K13+L13+M13+N13 -> 10 | P13: =O13/$O$16 -> 0.085470085
A14: Karisa | B14: 7 | C14: 1 | D14: 2 | F14: 1 | O14: =B14+C14+D14+E14+F14+G14+H14+I14+J14+K14+L14+M14+N14 -> 11 | P14: =O14/$O$16 -> 0.094017094
A15: Seidy | B15: 4 | C15: 2 | O15: =B15+C15+D15+E15+F15+G15+H15+I15+J15+K15+L15+M15+N15 -> 6 | P15: =O15/$O$16 -> 0.051282051
A16: Total | B16: =SUM(B3:B15) -> 93 | C16: =SUM(C3:C15) -> 15 | D16: =SUM(D3:D14) -> 3 | E16: =SUM(E3:E14) -> 1 | F16: =SUM(F3:F14) -> 4 | G16: =SUM(G3:G14) -> 1 | H16: =SUM(H3:H14) -> 0 | I16: =SUM(I3:I14) -> 0 | J16: =SUM(J3:J14) -> 0 | K16: =SUM(K3:K14) -> 0 | ... N16: =SUM(N3:N14) -> 0 | O16: =SUM(O2:O15) -> 117 | P16: =SUM(P2:P14) -> 0.94871795
A19: Produto | B19: Contador | C19: Corretor | D19: Médico | E19: Dentista | F19: RCPM | G19: Advogado | H19: Despachante | I19: Posto | J19: Cartório | K19: D & O | L19: Turismo | M19: Diversos
A20: Total | B20: =B49 -> 24 | C20: =C49 -> 16 | D20: =D49 -> 14 | E20: =E49 -> 7 | F20: =F49 -> 41 | G20: =G49 -> 3 | H20: =H49 -> 2 | I20: =I49 -> 0 | ... M20: =M49 -> 4
A21: Estado
A22: AC
A23: AL | F23: 1
A24: AM
A25: AP
A26: BA | F26: 1
A27: CE | F27: 1
A28: DF | C28: 1 | E28: 1 | F28: 1 | G28: 1
A29: ES | C29: 1 | D29: 1 | F29: 1 | L29: 2
A30: GO | C30: 2 | F30: 8
A31: MA | F31: 1
A32: MG | B32: 2 | C32: 2 | F32: 9 | L32: 1 | M32: 1
A33: MS | E33: 1 | F33: 2
A34: MT | B34: 1 | C34: 1 | D34: 1 | G34: 1
A35: PA
A36: PB
A37: PE | F37: 1
A38: PI | F38: 1
A39: PR | B39: 2 | C39: 1 | D39: 1 | F39: 5
A40: RJ | B40: 5 | D40: 1 | E40: 1 | F40: 1
A41: RN | E41: 1
A42: RO | B42: 1 | F42: 1
...

Sheet Agosto 2018
A1: ACIONAMENTO - JUNHO
A2: Regulador/Seguradora | B2: Argo | C2: AIG | D2: AXA | E2: CHUBB | F2: QBE | G2: FATOR | O2: Total
A3: Jéssica Rosa | B3: 8 | C3: 2 | O3: =B3+C3+D3+E3+F3+G3+H3+I3+J3+K3+L3+M3+N3 -> 10 | P3: =O3/$O$15 -> 0.076335878
A4: Teresa | B4: 11 | O4: =B4+C4+D4+E4+F4+G4+H4+I4+J4+K4+L4+M4+N4 -> 11 | P4: =O4/$O$15 -> 0.083969466
A5: João | B5: 8 | C5: 2 | G5: 1 | O5: =B5+C5+D5+E5+F5+G5+H5+I5+J5+K5+L5+M5+N5 -> 11 | P5: =O5/$O$15 -> 0.083969466
A6: Fernanda | B6: 8 | C6: 2 | F6: 1 | O6: =B6+C6+D6+E6+F6+G6+H6+I6+J6+K6+L6+M6+N6 -> 11 | P6: =O6/$O$15 -> 0.083969466
A7: Jéssica Carvalho | B7: 9 | C7: 2 | O7: =B7+C7+D7+E7+F7+G7+H7+I7+J7+K7+L7+M7+N7 -> 11 | P7: =O7/$O$15 -> 0.083969466
A8: Karina | B8: 10 | F8: 1 | O8: =B8+C8+D8+E8+F8+G8+H8+I8+J8+K8+L8+M8+N8 -> 11 | P8: =O8/$O$15 -> 0.083969466
A9: Ana | B9: 10 | C9: 1 | O9: =B9+C9+D9+E9+F9+G9+H9+I9+J9+K9+L9+M9+N9 -> 11 | P9: =O9/$O$15 -> 0.083969466
A10: Carlos | B10: 10 | C10: 1 | O10: =B10+C10+D10+E10+F10+G10+H10+I10+J10+K10+L10+M10+N10 -> 11 | P10: =O10/$O$15 -> 0.083969466
A11: Caroline | B11: 11 | O11: =B11+C11+D11+E11+F11+G11+H11+I11+J11+K11+L11+M11+N11 -> 11 | P11: =O11/$O$15 -> 0.083969466
A12: Everton | B12: 10 | C12: 1 | O12: =B12+C12+D12+E12+F12+G12+H12+I12+J12+K12+L12+M12+N12 -> 11 | P12: =O12/$O$15 -> 0.083969466
A13: Karisa | B13: 8 | C13: 3 | O13: =B13+C13+D13+E13+F13+G13+H13+I13+J13+K13+L13+M13+N13 -> 11 | P13: =O13/$O$15 -> 0.083969466
A14: Seidy | B14: 8 | C14: 2 | F14: 1 | O14: =B14+C14+D14+E14+F14+G14+H14+I14+J14+K14+L14+M14+N14 -> 11 | P14: =O14/$O$15 -> 0.083969466
A15: Total | B15: =SUM(B3:B14) -> 111 | C15: =SUM(C3:C14) -> 16 | D15: =SUM(D3:D13) -> 0 | E15: =SUM(E3:E13) -> 0 | F15: =SUM(F3:F14) -> 3 | G15: =SUM(G3:G13) -> 1 | H15: =SUM(H3:H13) -> 0 | I15: =SUM(I3:I13) -> 0 | J15: =SUM(J3:J13) -> 0 | K15: =SUM(K3:K13) -> 0 | L15: =SUM(L3:L13) -> 0 | M15: =SUM(M3:M13) -> 0 | N15: =SUM(N3:N13) -> 0 | O15: =SUM(O2:O14) -> 131 | P15: =SUM(P2:P13) -> 0.91603053
A18: Produto | B18: Contador | C18: Corretor | D18: Médico | E18: Dentista | F18: RCPM | G18: Advogado | H18: Despachante | I18: Posto | J18: Cartório | K18: D & O | L18: Turismo | M18: Diversos
A19: Total | B19: =B48 -> 9 | C19: =C48 -> 21 | D19: =D48 -> 28 | E19: =E48 -> 8 | F19: =F48 -> 53 | G19: =G48 -> 2 | H19: =H48 -> 0 | I19: =I48 -> 0 | ... M19: =M48 -> 3
A20: Estado
A21: AC
A22: AL
A23: AM
A24: AP
A25: BA | B25: 1 | C25: 1 | F25: 4
A26: CE | F26: 3
A27: DF | E27: 1
A28: ES | E28: 3 | L28: 1
A29: GO | F29: 9 | G29: 1
A30: MA | C30: 1 | F30: 1
A31: MG | C31: 3 | D31: 1 | F31: 4 | L31: 1
A32: MS | D32: 2 | F32: 5
A33: MT | D33: 1 | F33: 1
A34: PA
A35: PB | C35: 1 | F35: 2 | L35: 1
A36: PE | F36: 3
A37: PI
A38: PR | C38: 3 | E38: 1 | F38: 4 | L38: 1
A39: RJ | D39: 8 | E39: 2 | F39: 4 | M39: 2
A40: RN | F40: 4
A41: RO
A42: RR | F42: 1
...

Sheet Setembro 2018
A1: ACIONAMENTO - JUNHO
A2: Regulador/Seguradora | B2: Argo | C2: AIG | D2: AXA | E2: CHUBB | F2: QBE | G2: FATOR | O2: Total
A3: Teresa | B3: 9 | O3: =B3+C3+D3+E3+F3+G3+H3+I3+J3+K3+L3+M3+N3 -> 9 | P3: =O3/$O$15 -> 0.1011236
A4: João | B4: 7 | F4: 1 | O4: =B4+C4+D4+E4+F4+G4+H4+I4+J4+K4+L4+M4+N4 -> 8 | P4: =O4/$O$15 -> 0.08988764
A5: Fernanda | B5: 6 | C5: 2 | O5: =B5+C5+D5+E5+F5+G5+H5+I5+J5+K5+L5+M5+N5 -> 8 | P5: =O5/$O$15 -> 0.08988764
A6: Jéssica Carvalho | B6: 4 | C6: 1 | O6: =B6+C6+D6+E6+F6+G6+H6+I6+J6+K6+L6+M6+N6 -> 5 | P6: =O6/$O$15 -> 0.056179775
A7: Karina | B7: 6 | C7: 2 | O7: =B7+C7+D7+E7+F7+G7+H7+I7+J7+K7+L7+M7+N7 -> 8 | P7: =O7/$O$15 -> 0.08988764
A8: Ana | B8: 6 | C8: 2 | O8: =B8+C8+D8+E8+F8+G8+H8+I8+J8+K8+L8+M8+N8 -> 8 | P8: =O8/$O$15 -> 0.08988764
A9: Carlos | B9: 6 | C9: 2 | O9: =B9+C9+D9+E9+F9+G9+H9+I9+J9+K9+L9+M9+N9 -> 8 | P9: =O9/$O$15 -> 0.08988764
A10: Caroline | B10: 5 | C10: 3 | O10: =B10+C10+D10+E10+F10+G10+H10+I10+J10+K10+L10+M10+N10 -> 8 | P10: =O10/$O$15 -> 0.08988764
A11: Everton | B11: 6 | C11: 1 | O11: =B11+C11+D11+E11+F11+G11+H11+I11+J11+K11+L11+M11+N11 -> 7 | P11: =O11/$O$15 -> 0.078651685
A12: Karisa | B12: 6 | C12: 2 | O12: =B12+C12+D12+E12+F12+G12+H12+I12+J12+K12+L12+M12+N12 -> 8 | P12: =O12/$O$15 -> 0.08988764
A13: Seidy | B13: 6 | C13: 2 | O13: =B13+C13+D13+E13+F13+G13+H13+I13+J13+K13+L13+M13+N13 -> 8 | P13: =O13/$O$15 -> 0.08988764
A14: Jéssica Rosa | B14: 4 | O14: =B14+C14+D14+E14+F14+G14+H14+I14+J14+K14+L14+M14+N14 -> 4 | P14: =O14/$O$15 -> 0.04494382
A15: Total | B15: =SUM(B3:B14) -> 71 | C15: =SUM(C3:C14) -> 17 | D15: =SUM(D3:D13) -> 0 | E15: =SUM(E3:E13) -> 0 | F15: =SUM(F3:F14) -> 1 | G15: =SUM(G3:G13) -> 0 | H15: =SUM(H3:H13) -> 0 | I15: =SUM(I3:I13) -> 0 | J15: =SUM(J3:J13) -> 0 | K15: =SUM(K3:K13) -> 0 | L15: =SUM(L3:L13) -> 0 | M15: =SUM(M3:M13) -> 0 | N15: =SUM(N3:N13) -> 0 | O15: =SUM(O2:O14) -> 89 | P15: =SUM(P2:P13) -> 0.95505618
A18: Produto | B18: Contador | C18: Corretor | D18: Médico | E18: Dentista | F18: RCPM | G18: Advogado | H18: Despachante | I18: Posto | J18: Cartório | K18: D & O | L18: Turismo | M18: Diversos
A19: Total | B19: =B48 -> 8 | C19: =C48 -> 11 | D19: =D48 -> 26 | E19: =E48 -> 5 | F19: =F48 -> 28 | G19: =G48 -> 1 | H19: =H48 -> 0 | I19: =I48 -> 0 | ... M19: =M48 -> 4
A20: Estado
A21: AC
A22: AL
A23: AM
A24: AP
A25: BA | F25: 1 | L25: 1
A26: CE | F26: 3
A27: DF | D27: 1
A28: ES | D28: 2
A29: GO | D29: 1 | F29: 4
A30: MA | D30: 1 | F30: 1 | L30: 1
A31: MG | B31: 1 | C31: 2 | D31: 1 | E31: 1 | F31: 2
A32: MS | B32: 1 | D32: 2 | F32: 2
A33: MT | E33: 1
A34: PA | L34: 1
A35: PB | F35: 1
A36: PE | F36: 2
A37: PI
A38: PR | B38: 1 | C38: 4 | D38: 1 | E38: 1 | F38: 2
A39: RJ | B39: 1 | D39: 8 | E39: 1 | F39: 1 | G39: 1
A40: RN | F40: 1
A41: RO | C41: 1
A42: RR
...

Sheet Outubro 2018
A1: ACIONAMENTO - OUTUBRO
A2: Regulador/Seguradora | B2: Argo | C2: AIG | D2: AXA | E2: CHUBB | F2: QBE | G2: FATOR | O2: Total
A3: João | B3: 6 | C3: 7 | O3: =B3+C3+D3+E3+F3+G3+H3+I3+J3+K3+L3+M3+N3 -> 13 | P3: =O3/$O$14 -> 0.1031746
A4: Fernanda | B4: 4 | D4: 1 | O4: =B4+C4+D4+E4+F4+G4+H4+I4+J4+K4+L4+M4+N4 -> 5 | P4: =O4/$O$14 -> 0.03968254
A5: Ana | B5: 9 | C5: 1 | F5: 2 | O5: =B5+C5+D5+E5+F5+G5+H5+I5+J5+K5+L5+M5+N5 -> 12 | P5: =O5/$O$14 -> 0.095238095
A6: Carlos | B6: 10 | C6: 3 | O6: =B6+C6+D6+E6+F6+G6+H6+I6+J6+K6+L6+M6+N6 -> 13 | P6: =O6/$O$14 -> 0.1031746
A7: Caroline | B7: 9 | C7: 3 | O7: =B7+C7+D7+E7+F7+G7+H7+I7+J7+K7+L7+M7+N7 -> 12 | P7: =O7/$O$14 -> 0.095238095
A8: Everton | B8: 11 | O8: =B8+C8+D8+E8+F8+G8+H8+I8+J8+K8+L8+M8+N8 -> 11 | P8: =O8/$O$14 -> 0.087301587
A9: Emilio | B9: 5 | F9: 1 | O9: =B9+C9+D9+E9+F9+G9+H9+I9+J9+K9+L9+M9+N9 -> 6 | P9: =O9/$O$14 -> 0.047619048
A10: Karisa | B10: 7 | C10: 6 | E10: 1 | F10: 1 | O10: =B10+C10+D10+E10+F10+G10+H10+I10+J10+K10+L10+M10+N10 -> 15 | P10: =O10/$O$14 -> 0.11904762
A11: Seidy | B11: 5 | C11: 6 | F11: 3 | O11: =B11+C11+D11+E11+F11+G11+H11+I11+J11+K11+L11+M11+N11 -> 14 | P11: =O11/$O$14 -> 0.11111111
A12: Jéssica Rosa | B12: 12 | O12: =B12+C12+D12+E12+F12+G12+H12+I12+J12+K12+L12+M12+N12 -> 12 | P12: =O12/$O$14 -> 0.095238095
A13: Teresa | B13: 3 | C13: 8 | E13: 2 | O13: =B13+C13+D13+E13+F13+G13+H13+I13+J13+K13+L13+M13+N13 -> 13 | P13: =O13/$O$14 -> 0.1031746
A14: Total | B14: =SUM(B3:B13) -> 81 | C14: =SUM(C3:C13) -> 34 | D14: =SUM(D3:D13) -> 1 | E14: =SUM(E3:E13) -> 3 | F14: =SUM(F3:F13) -> 7 | G14: =SUM(G3:G13) -> 0 | H14: =SUM(H3:H13) -> 0 | I14: =SUM(I3:I13) -> 0 | ... N14: =SUM(N3:N13) -> 0 | O14: =SUM(O2:O13) -> 126 | P14: =SUM(P2:P13) -> 1
A17: Produto | B17: Contador | C17: Corretor | D17: Médico | E17: Dentista | F17: RCPM | G17: Advogado | H17: Despachante | I17: Posto | J17: Cartório | K17: D & O | L17: Turismo | M17: Diversos
A18: Total | B18: =B47 -> 28 | C18: =C47 -> 20 | D18: =D47 -> 17 | E18: =E47 -> 7 | F18: =F47 -> 32 | G18: =G47 -> 4 | H18: =H47 -> 2 | I18: =I47 -> 0 | ... M18: =M47 -> 1
A19: Estado
A20: AC
A21: AL
A22: AM
A23: AP
A24: BA | D24: 1
A25: CE | B25: 1 | F25: 7
A26: DF | B26: 2 | D26: 1 | L26: 1
A27: ES | L27: 1
A28: GO | B28: 1 | C28: 1 | F28: 7
A29: MA
A30: MG | B30: 5 | C30: 2 | F30: 4 | L30: 4
A31: MS | F31: 2
A32: MT
A33: PA
A34: PB
A35: PE
A36: PI | F36: 1
A37: PR | B37: 3 | C37: 4 | D37: 1 | E37: 7 | F37: 1 | G37: 1
A38: RJ | B38: 1 | D38: 4 | F38: 2 | L38: 1
A39: RN | C39: 1 | F39: 2
A40: RO
A41: RR
A42: RS | F42: 2 | J42: 1 | L42: 1
...

Sheet Novembro 2018
A1: ACIONAMENTO - NOVEMBRO
A2: Regulador/Seguradora | B2: Argo | C2: AIG | D2: AXA | E2: CHUBB | F2: QBE | G2: FATOR | O2: Total
A3: Everton | B3: 14 | O3: =B3+C3+D3+E3+F3+G3+H3+I3+J3+K3+L3+M3+N3 -> 14 | P3: =O3/$O$14 -> 0.10769231
A4: Karisa | B4: 3 | C4: 7 | D4: 2 | O4: =B4+C4+D4+E4+F4+G4+H4+I4+J4+K4+L4+M4+N4 -> 12 | P4: =O4/$O$14 -> 0.092307692
A5: Seidy | B5: 8 | C5: 4 | D5: 1 | F5: 1 | O5: =B5+C5+D5+E5+F5+G5+H5+I5+J5+K5+L5+M5+N5 -> 14 | P5: =O5/$O$14 -> 0.10769231
A6: Jéssica Rosa | B6: 13 | D6: 1 | F6: 1 | O6: =B6+C6+D6+E6+F6+G6+H6+I6+J6+K6+L6+M6+N6 -> 15 | P6: =O6/$O$14 -> 0.11538462
A7: Teresa | B7: 6 | C7: 7 | G7: 1 | O7: =B7+C7+D7+E7+F7+G7+H7+I7+J7+K7+L7+M7+N7 -> 14 | P7: =O7/$O$14 -> 0.10769231
A8: João | B8: 9 | C8: 3 | D8: 1 | O8: =B8+C8+D8+E8+F8+G8+H8+I8+J8+K8+L8+M8+N8 -> 13 | P8: =O8/$O$14 -> 0.1
A9: Emilio | B9: 7 | O9: =B9+C9+D9+E9+F9+G9+H9+I9+J9+K9+L9+M9+N9 -> 7 | P9: =O9/$O$14 -> 0.053846154
A10: Ana | B10: 14 | O10: =B10+C10+D10+E10+F10+G10+H10+I10+J10+K10+L10+M10+N10 -> 14 | P10: =O10/$O$14 -> 0.10769231
A11: Carlos | B11: 13 | D11: 2 | O11: =B11+C11+D11+E11+F11+G11+H11+I11+J11+K11+L11+M11+N11 -> 15 | P11: =O11/$O$14 -> 0.11538462
A12: Caroline | B12: 6 | C12: 4 | O12: =B12+C12+D12+E12+F12+G12+H12+I12+J12+K12+L12+M12+N12 -> 10 | P12: =O12/$O$14 -> 0.076923077
A13: Diego | C13: 2 | O13: =B13+C13+D13+E13+F13+G13+H13+I13+J13+K13+L13+M13+N13 -> 2 | P13: =O13/$O$14 -> 0.015384615
A14: Total | B14: =SUM(B3:B13) -> 93 | C14: =SUM(C3:C13) -> 27 | D14: =SUM(D3:D13) -> 7 | E14: =SUM(E3:E13) -> 0 | F14: =SUM(F3:F13) -> 2 | G14: =SUM(G3:G13) -> 1 | H14: =SUM(H3:H13) -> 0 | I14: =SUM(I3:I13) -> 0 | ... N14: =SUM(N3:N13) -> 0 | O14: =SUM(O2:O13) -> 130 | P14: =SUM(P2:P13) -> 1
A17: Produto | B17: Contador | C17: Corretor | D17: Médico | E17: Dentista | F17: RCPM | G17: Advogado | H17: Despachante | I17: Posto | J17: Cartório | K17: D & O | L17: Turismo | M17: Diversos
A18: Total | B18: =B47 -> 15 | C18: =C47 -> 17 | D18: =D47 -> 24 | E18: =E47 -> 12 | F18: =F47 -> 41 | G18: =G47 -> 5 | H18: =H47 -> 1 | I18: =I47 -> 0 | ... M18: =M47 -> 6
A19: Estado
A20: AC
A21: AL
A22: AM
A23: AP
A24: BA | C24: 1 | D24: 1 | F24: 1
A25: CE | F25: 2
A26: DF
A27: ES | L27: 1
A28: GO | B28: 1 | F28: 8
A29: MA | D29: 1
A30: MG | B30: 1 | D30: 2 | F30: 9 | M30: 1
A31: MS | D31: 1 | F31: 1
A32: MT | C32: 1 | M32: 1
A33: PA | F33: 1
A34: PB | E34: 2 | F34: 2
A35: PE | F35: 1
A36: PI | F36: 1
A37: PR | C37: 6 | D37: 2 | E37: 7 | F37: 1 | G37: 1
A38: RJ | B38: 1 | D38: 5 | E38: 2 | F38: 1 | L38: 1
A39: RN | F39: 2
A40: RO
A41: RR
A42: RS | D42: 1 | F42: 2 | G42: 1 | L42: 1 | M42: 1
...

Sheet Dezembro 2018
A1: ACIONAMENTO - NOVEMBRO
A2: Regulador/Seguradora | B2: Argo | C2: AIG | D2: AXA | E2: CHUBB | F2: QBE | G2: FATOR | O2: Total
A3: Caroline | B3: 8 | C3: 5 | D3: 1 | O3: =B3+C3+D3+E3+F3+G3+H3+I3+J3+K3+L3+M3+N3 -> 14 | P3: =O3/$O$14 -> 0.11666667
A4: Everton | B4: 13 | O4: =B4+C4+D4+E4+F4+G4+H4+I4+J4+K4+L4+M4+N4 -> 13 | P4: =O4/$O$14 -> 0.10833333
A5: Karisa | B5: 11 | C5: 3 | D5: 1 | O5: =B5+C5+D5+E5+F5+G5+H5+I5+J5+K5+L5+M5+N5 -> 15 | P5: =O5/$O$14 -> 0.125
A6: Seidy | B6: 12 | C6: 2 | D6: 1 | O6: =B6+C6+D6+E6+F6+G6+H6+I6+J6+K6+L6+M6+N6 -> 15 | P6: =O6/$O$14 -> 0.125
A7: Jéssica Rosa | B7: 12 | C7: 2 | D7: 1 | O7: =B7+C7+D7+E7+F7+G7+H7+I7+J7+K7+L7+M7+N7 -> 15 | P7: =O7/$O$14 -> 0.125
A8: Teresa | B8: 2 | C8: 1 | O8: =B8+C8+D8+E8+F8+G8+H8+I8+J8+K8+L8+M8+N8 -> 3 | P8: =O8/$O$14 -> 0.025
A9: João | B9: 8 | C9: 1 | O9: =B9+C9+D9+E9+F9+G9+H9+I9+J9+K9+L9+M9+N9 -> 9 | P9: =O9/$O$14 -> 0.075
A10: Emilio | B10: 11 | C10: 1 | D10: 3 | O10: =B10+C10+D10+E10+F10+G10+H10+I10+J10+K10+L10+M10+N10 -> 15 | P10: =O10/$O$14 -> 0.125
A11: Ana | B11: 6 | O11: =B11+C11+D11+E11+F11+G11+H11+I11+J11+K11+L11+M11+N11 -> 6 | P11: =O11/$O$14 -> 0.05
A12: Carlos | B12: 11 | C12: 4 | O12: =B12+C12+D12+E12+F12+G12+H12+I12+J12+K12+L12+M12+N12 -> 15 | P12: =O12/$O$14 -> 0.125
A13: Diego | O13: =B13+C13+D13+E13+F13+G13+H13+I13+J13+K13+L13+M13+N13 -> 0 | P13: =O13/$O$14 -> 0
A14: Total | B14: =SUM(B3:B13) -> 94 | C14: =SUM(C3:C13) -> 19 | D14: =SUM(D3:D13) -> 7 | E14: =SUM(E3:E13) -> 0 | F14: =SUM(F3:F13) -> 0 | G14: =SUM(G3:G13) -> 0 | H14: =SUM(H3:H13) -> 0 | I14: =SUM(I3:I13) -> 0 | ... N14: =SUM(N3:N13) -> 0 | O14: =SUM(O2:O13) -> 120 | P14: =SUM(P2:P13) -> 1
A17: Produto | B17: Contador | C17: Corretor | D17: Médico | E17: Dentista | F17: RCPM | G17: Advogado | H17: Despachante | I17: Posto | J17: Cartório | K17: D & O | L17: Turismo | M17: Diversos
A18: Total | B18: =B47 -> 21 | C18: =C47 -> 12 | D18: =D47 -> 18 | E18: =E47 -> 1 | F18: =F47 -> 56 | G18: =G47 -> 1 | H18: =H47 -> 1 | I18: =I47 -> 0 | ... M18: =M47 -> 5
A19: Estado
A20: AC
A21: AL
A22: AM
A23: AP
A24: BA | F24: 3
A25: CE | F25: 7
A26: DF | B26: 1 | F26: 2
A27: ES | B27: 1 | F27: 2
A28: GO | F28: 11
A29: MA
A30: MG | B30: 2 | C30: 1 | F30: 8
A31: MS | F31: 1 | M31: 1
A32: MT | F32: 2
A33: PA | F33: 1
A34: PB | F34: 2
A35: PE
A36: PI
A37: PR | B37: 1 | C37: 1 | D37: 4 | F37: 1
A38: RJ | B38: 3 | D38: 6 | E38: 1 | F38: 4 | L38: 1
A39: RN | F39: 1
A40: RO | F40: 1
A41: RR
A42: RS | B42: 1 | C42: 1 | D42: 1 | F42: 3
...

Sheet Janeiro 2019
A1: ACIONAMENTO - JANEIRO
A2: Regulador/Seguradora | B2: Argo | C2: AIG | D2: AXA | E2: CHUBB | F2: QBE | G2: FATOR | O2: Total
A3: Caroline | B3: 17 | C3: 1 | D3: 1 | O3: =B3+C3+D3+E3+F3+G3+H3+I3+J3+K3+L3+M3+N3 -> 19 | P3: =O3/$O$13 -> 0.16239316
A4: Everton | B4: 17 | E4: 1 | O4: =B4+C4+D4+E4+F4+G4+H4+I4+J4+K4+L4+M4+N4 -> 18 | P4: =O4/$O$13 -> 0.15384615
A5: Karisa | B5: 4 | O5: =B5+C5+D5+E5+F5+G5+H5+I5+J5+K5+L5+M5+N5 -> 4 | P5: =O5/$O$13 -> 0.034188034
A6: Seidy | B6: 5 | C6: 1 | E6: 1 | O6: =B6+C6+D6+E6+F6+G6+H6+I6+J6+K6+L6+M6+N6 -> 7 | P6: =O6/$O$13 -> 0.05982906
A7: Jéssica Rosa | B7: 2 | D7: 2 | O7: =B7+C7+D7+E7+F7+G7+H7+I7+J7+K7+L7+M7+N7 -> 4 | P7: =O7/$O$13 -> 0.034188034
A8: Teresa | B8: 6 | C8: 6 | G8: 1 | O8: =B8+C8+D8+E8+F8+G8+H8+I8+J8+K8+L8+M8+N8 -> 13 | P8: =O8/$O$13 -> 0.11111111
A9: João | B9: 14 | C9: 3 | O9: =B9+C9+D9+E9+F9+G9+H9+I9+J9+K9+L9+M9+N9 -> 17 | P9: =O9/$O$13 -> 0.14529915
A10: Ana | B10: 8 | C10: 2 | D10: 2 | E10: 1 | F10: 2 | O10: =B10+C10+D10+E10+F10+G10+H10+I10+J10+K10+L10+M10+N10 -> 15 | P10: =O10/$O$13 -> 0.12820513
A11: Carlos | B11: 15 | C11: 3 | D11: 2 | O11: =B11+C11+D11+E11+F11+G11+H11+I11+J11+K11+L11+M11+N11 -> 20 | P11: =O11/$O$13 -> 0.17094017
A12: Diego | O12: =B12+C12+D12+E12+F12+G12+H12+I12+J12+K12+L12+M12+N12 -> 0 | P12: =O12/$O$13 -> 0
A13: Total | B13: =SUM(B3:B12) -> 88 | C13: =SUM(C3:C12) -> 16 | D13: =SUM(D3:D12) -> 7 | E13: =SUM(E3:E12) -> 3 | F13: =SUM(F3:F12) -> 2 | G13: =SUM(G3:G12) -> 1 | H13: =SUM(H3:H12) -> 0 | I13: =SUM(I3:I12) -> 0 | ... N13: =SUM(N3:N12) -> 0 | O13: =SUM(O2:O12) -> 117 | P13: =SUM(P2:P12) -> 1
A16: Produto | B16: Contador | C16: Corretor | D16: Médico | E16: Dentista | F16: RCPM | G16: Advogado | H16: Despachante | I16: Posto | J16: Cartório | K16: D & O | L16: Turismo | M16: Diversos
A17: Total | B17: =B46 -> 11 | C17: =C46 -> 11 | D17: =D46 -> 11 | E17: =E46 -> 5 | F17: =F46 -> 63 | G17: =G46 -> 3 | H17: =H46 -> 2 | I17: =I46 -> 0 | ... M17: =M46 -> 7
A18: Estado
A19: AC
A20: AL
A21: AM
A22: AP
A23: BA | F23: 5
A24: CE | F24: 4
A25: DF | M25: 1
A26: ES | B26: 1 | E26: 1 | F26: 1
A27: GO | C27: 1 | F27: 16
A28: MA
A29: MG | B29: 1 | C29: 1 | F29: 11
A30: MS | C30: 1 | F30: 1
A31: MT | F31: 1
A32: PA | F32: 1 | G32: 1
A33: PB | F33: 2
A34: PE | F34: 1
A35: PI | F35: 1
A36: PR | C36: 1 | D36: 1 | E36: 1 | F36: 2
A37: RJ | B37: 3 | D37: 2 | F37: 3 | L37: 2 | M37: 2
A38: RN | F38: 1
A39: RO | F39: 1
A40: RR
A41: RS
A42: SC | E42: 2 | F42: 4 | G42: 2 | H42: 2 | M42: 1
...

Sheet Fevereiro 2019
A1: ACIONAMENTO - FEVEREIRO
A2: Regulador/Seguradora | B2: Argo | C2: AIG | D2: AXA | E2: CHUBB | F2: QBE | G2: FATOR | O2: Total
A3: Teresa | B3: 7 | C3: 5 | D3: 1 | F3: 1 | O3: =B3+C3+D3+E3+F3+G3+H3+I3+J3+K3+L3 -> 14 | P3: =O3/$O$13 -> 0.14583333
A4: João | B4: 11 | C4: 1 | D4: 1 | F4: 1 | O4: =B4+C4+D4+E4+F4+G4+H4+I4+J4+K4+L4 -> 14 | P4: =O4/$O$13 -> 0.14583333
A5: Ana | B5: 7 | C5: 1 | D5: 2 | F5: 1 | G5: 1 | O5: =B5+C5+D5+E5+F5+G5+H5+I5+J5+K5+L5 -> 12 | P5: =O5/$O$13 -> 0.125
A6: Carlos | B6: 9 | C6: 2 | D6: 1 | E6: 1 | O6: =B6+C6+D6+E6+F6+G6+H6+I6+J6+K6+L6 -> 13 | P6: =O6/$O$13 -> 0.13541667
A7: Carol | B7: 3 | D7: 1 | O7: =B7+C7+D7+E7+F7+G7+H7+I7+J7+K7+L7 -> 4 | P7: =O7/$O$13 -> 0.041666667
A8: Everton | B8: 11 | C8: 1 | D8: 1 | O8: =B8+C8+D8+E8+F8+G8+H8+I8+J8+K8+L8 -> 13 | P8: =O8/$O$13 -> 0.13541667
A9: Karisa | B9: 8 | C9: 3 | D9: 2 | O9: =B9+C9+D9+E9+F9+G9+H9+I9+J9+K9+L9 -> 13 | P9: =O9/$O$13 -> 0.13541667
A10: Seidy | B10: 9 | C10: 1 | D10: 2 | F10: 1 | O10: =B10+C10+D10+E10+F10+G10+H10+I10+J10+K10+L10 -> 13 | P10: =O10/$O$13 -> 0.13541667
A11: Jéssica Rosa | O11: =B11+C11+D11+E11+F11+G11+H11+I11+J11+K11+L11 -> 0 | P11: =O11/$O$13 -> 0
A12: Diego | O12: =B12+C12+D12+E12+F12+G12+H12+I12+J12+K12+L12 -> 0 | P12: =O12/$O$13 -> 0
A13: Total | B13: =SUM(B3:B12) -> 65 | C13: =SUM(C3:C12) -> 14 | D13: =SUM(D3:D12) -> 11 | E13: =SUM(E3:E12) -> 1 | F13: =SUM(F3:F12) -> 4 | G13: =SUM(G3:G12) -> 1 | H13: =SUM(H3:H12) -> 0 | I13: =SUM(I3:I12) -> 0 | ... O13: =SUM(O3:O12) -> 96 | P13: =SUM(P2:P12) -> 1
A16: Produto | B16: Contador | C16: Corretor | D16: Médico | E16: Dentista | F16: RCPM | G16: Advogado | H16: Despachante | I16: Posto | J16: Cartório | K16: D & O | L16: Turismo | M16: Diversos
A17: Total | B17: =B46 -> 21 | C17: =C46 -> 13 | D17: =D46 -> 23 | E17: =E46 -> 8 | F17: =F46 -> 10 | G17: =G46 -> 7 | H17: =H46 -> 0 | I17: =I46 -> 0 | ... M17: =M46 -> 8
A18: Estado
A19: AC | C19: 1
A20: AL
A21: AM
A22: AP
A23: BA | F23: 1
A24: CE
A25: DF
A26: ES | B26: 2 | E26: 1 | L26: 1
A27: GO | F27: 2
A28: MA
A29: MG | B29: 2 | C29: 2 | F29: 4 | L29: 1
A30: MS | C30: 1 | D30: 6
A31: MT | E31: 1
A32: PA
A33: PB | F33: 1
A34: PE | D34: 1
A35: PI
A36: PR | C36: 1 | D36: 1 | E36: 1 | F36: 1 | G36: 1 | M36: 1
A37: RJ | C37: 2 | D37: 2 | E37: 2 | L37: 1
A38: RN
A39: RO | F39: 1
A40: RR
A41: RS | B41: 2 | D41: 1 | M41: 3
A42: SC | B42: 2 | D42: 1 | G42: 4
...

Sheet Março 2019
A1: ACIONAMENTO - MARÇO
A2: Regulador/Seguradora | B2: Argo | C2: AIG | D2: AXA | E2: CHUBB | F2: QBE | G2: FATOR | O2: Total
A3: Carlos | B3: 10 | C3: 1 | D3: 1 | O3: =B3+C3+D3+E3+F3+G3+H3+I3+J3+K3+L3 -> 12 | P3: =O3/$O$13 -> 0.14285714
A4: Carol | B4: 9 | C4: 1 | D4: 1 | O4: =B4+C4+D4+E4+F4+G4+H4+I4+J4+K4+L4 -> 11 | P4: =O4/$O$13 -> 0.13095238
A5: Everton | B5: 8 | O5: =B5+C5+D5+E5+F5+G5+H5+I5+J5+K5+L5 -> 8 | P5: =O5/$O$13 -> 0.095238095
A6: Karisa | B6: 10 | C6: 1 | D6: 1 | O6: =B6+C6+D6+E6+F6+G6+H6+I6+J6+K6+L6 -> 12 | P6: =O6/$O$13 -> 0.14285714
A7: Seidy | B7: 10 | D7: 1 | O7: =B7+C7+D7+E7+F7+G7+H7+I7+J7+K7+L7 -> 11 | P7: =O7/$O$13 -> 0.13095238
A8: Teresa | B8: 7 | C8: 2 | D8: 1 | O8: =B8+C8+D8+E8+F8+G8+H8+I8+J8+K8+L8 -> 10 | P8: =O8/$O$13 -> 0.11904762
A9: João | B9: 9 | D9: 1 | O9: =B9+C9+D9+E9+F9+G9+H9+I9+J9+K9+L9 -> 10 | P9: =O9/$O$13 -> 0.11904762
A10: Ana | C10: 3 | D10: 3 | E10: 3 | G10: 1 | O10: =B10+C10+D10+E10+F10+G10+H10+I10+J10+K10+L10 -> 10 | P10: =O10/$O$13 -> 0.11904762
A11: Jéssica Rosa | O11: =B11+C11+D11+E11+F11+G11+H11+I11+J11+K11+L11 -> 0 | P11: =O11/$O$13 -> 0
A12: Diego | O12: =B12+C12+D12+E12+F12+G12+H12+I12+J12+K12+L12 -> 0 | P12: =O12/$O$13 -> 0
A13: Total | B13: =SUM(B3:B12) -> 63 | C13: =SUM(C3:C12) -> 8 | D13: =SUM(D3:D12) -> 9 | E13: =SUM(E3:E12) -> 3 | F13: =SUM(F3:F12) -> 0 | G13: =SUM(G3:G12) -> 1 | H13: =SUM(H3:H12) -> 0 | I13: =SUM(I3:I12) -> 0 | ... O13: =SUM(O3:O12) -> 84 | P13: =SUM(P2:P12) -> 1
A16: Produto | B16: Contador | C16: Corretor | D16: Médico | E16: Dentista | F16: RCPM | G16: Advogado | H16: Despachante | I16: Posto | J16: Cartório | K16: D & O | L16: Turismo | M16: Diversos
A17: Total | B17: =B46 -> 14 | C17: =C46 -> 18 | D17: =D46 -> 28 | E17: =E46 -> 2 | F17: =F46 -> 0 | G17: =G46 -> 9 | H17: =H46 -> 2 | I17: =I46 -> 0 | ... M17: =M46 -> 8
A18: Estado
A19: AC
A20: AL | D20: 1
A21: AM | B21: 1
A22: AP
A23: BA | C23: 1
A24: CE
A25: DF | C25: 1 | G25: 1
A26: ES | D26: 2
A27: GO | M27: 1
A28: MA
A29: MG | C29: 7 | G29: 1 | M29: 1
A30: MS | D30: 1
A31: MT
A32: PA
A33: PB
A34: PE
A35: PI
A36: PR | B36: 1 | D36: 2 | E36: 2 | G36: 2 | H36: 2 | M36: 1
A37: RJ | B37: 1 | D37: 10 | G37: 1
A38: RN
A39: RO | M39: 1
A40: RR
A41: RS | C41: 2
A42: SC | C42: 1 | D42: 3 | G42: 1 | M42: 1
...

Sheet Abril 2019
A1: ACIONAMENTO - ABRIL
A2: Regulador/Seguradora | B2: Argo | C2: AIG | D2: AXA | E2: CHUBB | F2: QBE | G2: FATOR | O2: Total
A3: Carlos | B3: 6 | E3: 1 | O3: =B3+C3+D3+E3+F3+G3+H3+I3+J3+K3+L3 -> 7 | P3: =O3/$O$13 -> 0.085365854
A4: Carol | B4: 10 | C4: 2 | D4: 1 | O4: =B4+C4+D4+E4+F4+G4+H4+I4+J4+K4+L4 -> 13 | P4: =O4/$O$13 -> 0.15853659
A5: Everton | B5: 5 | O5: =B5+C5+D5+E5+F5+G5+H5+I5+J5+K5+L5 -> 5 | P5: =O5/$O$13 -> 0.06097561
A6: Karisa | B6: 12 | C6: 1 | O6: =B6+C6+D6+E6+F6+G6+H6+I6+J6+K6+L6 -> 13 | P6: =O6/$O$13 -> 0.15853659
A7: Seidy | B7: 10 | C7: 2 | O7: =B7+C7+D7+E7+F7+G7+H7+I7+J7+K7+L7 -> 12 | P7: =O7/$O$13 -> 0.14634146
A8: Teresa | B8: 7 | C8: 5 | O8: =B8+C8+D8+E8+F8+G8+H8+I8+J8+K8+L8 -> 12 | P8: =O8/$O$13 -> 0.14634146
A9: João | B9: 8 | C9: 2 | D9: 1 | O9: =B9+C9+D9+E9+F9+G9+H9+I9+J9+K9+L9 -> 11 | P9: =O9/$O$13 -> 0.13414634
A10: Ana | C10: 5 | F10: 4 | O10: =B10+C10+D10+E10+F10+G10+H10+I10+J10+K10+L10 -> 9 | P10: =O10/$O$13 -> 0.1097561
A11: Jéssica Rosa | O11: =B11+C11+D11+E11+F11+G11+H11+I11+J11+K11+L11 -> 0 | P11: =O11/$O$13 -> 0
A12: Diego | O12: =B12+C12+D12+E12+F12+G12+H12+I12+J12+K12+L12 -> 0 | P12: =O12/$O$13 -> 0
A13: Total | B13: =SUM(B3:B12) -> 58 | C13: =SUM(C3:C12) -> 17 | D13: =SUM(D3:D12) -> 2 | E13: =SUM(E3:E12) -> 1 | F13: =SUM(F3:F12) -> 4 | G13: =SUM(G3:G12) -> 0 | H13: =SUM(H3:H12) -> 0 | I13: =SUM(I3:I12) -> 0 | ... O13: =SUM(O3:O12) -> 82 | P13: =SUM(P2:P12) -> 1
A16: Produto | B16: Contador | C16: Corretor | D16: Médico | E16: Dentista | F16: RCPM | G16: Advogado | H16: Despachante | I16: Posto | J16: Cartório | K16: D & O | L16: Turismo | M16: Diversos
A17: Total | B17: =B46 -> 16 | C17: =C46 -> 15 | D17: =D46 -> 26 | E17: =E46 -> 5 | F17: =F46 -> 0 | G17: =G46 -> 2 | H17: =H46 -> 0 | I17: =I46 -> 0 | ... M17: =M46 -> 8
A18: Estado
A19: AC
A20: AL
A21: AM
A22: AP
A23: BA | D23: 1
A24: CE
A25: DF | D25: 1 | E25: 1
A26: ES | B26: 1 | L26: 1
A27: GO | J27: 1
A28: MA
A29: MG | B29: 3 | C29: 2 | M29: 1
A30: MS | D30: 1
A31: MT | B31: 1
A32: PA
A33: PB
A34: PE
A35: PI
A36: PR | C36: 1 | D36: 1
A37: RJ | D37: 12 | E37: 1 | G37: 1 | L37: 4 | M37: 1
A38: RN | C38: 1
A39: RO | B39: 1
A40: RR | D40: 1
A41: RS | C41: 1 | D41: 1
A42: SC | C42: 1 | D42: 3 | G42: 1
...

Sheet Maio 2019
A1: ACIONAMENTO - MAIO
A2: Regulador/Seguradora | B2: Argo | C2: AIG | D2: AXA | E2: CHUBB | F2: QBE | G2: FATOR | O2: Total
A3: Carlos | B3: 9 | C3: 1 | E3: 1 | F3: 1 | O3: =B3+C3+D3+E3+F3+G3+H3+I3+J3+K3+L3 -> 12 | P3: =O3/$O$13 -> 0.14457831
A4: Carol | B4: 9 | C4: 2 | E4: 1 | O4: =B4+C4+D4+E4+F4+G4+H4+I4+J4+K4+L4 -> 12 | P4: =O4/$O$13 -> 0.14457831
A5: Everton | B5: 4 | O5: =B5+C5+D5+E5+F5+G5+H5+I5+J5+K5+L5 -> 4 | P5: =O5/$O$13 -> 0.048192771
A6: Karisa | B6: 6 | C6: 3 | O6: =B6+C6+D6+E6+F6+G6+H6+I6+J6+K6+L6 -> 9 | P6: =O6/$O$13 -> 0.10843373
A7: Seidy | B7: 9 | C7: 1 | O7: =B7+C7+D7+E7+F7+G7+H7+I7+J7+K7+L7 -> 10 | P7: =O7/$O$13 -> 0.12048193
A8: Teresa | B8: 9 | C8: 5 | O8: =B8+C8+D8+E8+F8+G8+H8+I8+J8+K8+L8 -> 14 | P8: =O8/$O$13 -> 0.1686747
A9: João | B9: 6 | C9: 1 | E9: 2 | F9: 1 | O9: =B9+C9+D9+E9+F9+G9+H9+I9+J9+K9+L9 -> 10 | P9: =O9/$O$13 -> 0.12048193
A10: Ana | B10: 4 | C10: 2 | D10: 1 | E10: 2 | F10: 2 | O10: =B10+C10+D10+E10+F10+G10+H10+I10+J10+K10+L10 -> 11 | P10: =O10/$O$13 -> 0.13253012
A11: Jéssica Rosa | O11: =B11+C11+D11+E11+F11+G11+H11+I11+J11+K11+L11 -> 0 | P11: =O11/$O$13 -> 0
A12: Diego | C12: 1 | O12: =B12+C12+D12+E12+F12+G12+H12+I12+J12+K12+L12 -> 1 | P12: =O12/$O$13 -> 0.012048193
A13: Total | B13: =SUM(B3:B12) -> 56 | C13: =SUM(C3:C12) -> 16 | D13: =SUM(D3:D12) -> 1 | E13: =SUM(E3:E12) -> 6 | F13: =SUM(F3:F12) -> 4 | G13: =SUM(G3:G12) -> 0 | H13: =SUM(H3:H12) -> 0 | I13: =SUM(I3:I12) -> 0 | ... O13: =SUM(O3:O12) -> 83 | P13: =SUM(P2:P12) -> 1
A16: Produto | B16: Contador | C16: Corretor | D16: Médico | E16: Dentista | F16: RCPM | G16: Advogado | H16: Despachante | I16: Posto | J16: Cartório | K16: D & O | L16: Turismo | M16: Diversos
A17: Total | B17: =B46 -> 13 | C17: =C46 -> 20 | D17: =D46 -> 25 | E17: =E46 -> 4 | F17: =F46 -> 0 | G17: =G46 -> 3 | H17: =H46 -> 1 | I17: =I46 -> 0 | ... M17: =M46 -> 7
A18: Estado
A19: AC
A20: AL
A21: AM | G21: 1
A22: AP
A23: BA | C23: 1 | M23: 1
A24: CE
A25: DF | B25: 1
A26: ES | E26: 1 | L26: 1
A27: GO
A28: MA
A29: MG | B29: 3 | C29: 5 | D29: 2 | M29: 1
A30: MS | D30: 2
A31: MT | D31: 1
A32: PA
A33: PB
A34: PE
A35: PI
A36: PR | B36: 1 | D36: 1 | E36: 1
A37: RJ | D37: 6 | E37: 2
A38: RN | D38: 2
A39: RO | D39: 1
A40: RR
A41: RS | B41: 1 | C41: 3 | L41: 1 | M41: 1
A42: SC | B42: 1 | D42: 4 | G42: 1 | L42: 1
...

Sheet Junho 2019
A1: ACIONAMENTO - MAIO
A2: Regulador/Seguradora | B2: Argo | C2: AIG | D2: AXA | E2: CHUBB | F2: QBE | G2: FATOR | O2: Total
A3: Carlos | B3: 5 | O3: =B3+C3+D3+E3+F3+G3+H3+I3+J3+K3+L3 -> 5 | P3: =O3/$O$13 -> 0.090909091
A4: Carol | B4: 5 | C4: 4 | O4: =B4+C4+D4+E4+F4+G4+H4+I4+J4+K4+L4 -> 9 | P4: =O4/$O$13 -> 0.16363636
A5: Everton | B5: 4 | C5: 2 | O5: =B5+C5+D5+E5+F5+G5+H5+I5+J5+K5+L5 -> 6 | P5: =O5/$O$13 -> 0.10909091
A6: Karisa | B6: 5 | O6: =B6+C6+D6+E6+F6+G6+H6+I6+J6+K6+L6 -> 5 | P6: =O6/$O$13 -> 0.090909091
A7: Seidy | B7: 2 | O7: =B7+C7+D7+E7+F7+G7+H7+I7+J7+K7+L7 -> 2 | P7: =O7/$O$13 -> 0.036363636
A8: Teresa | B8: 4 | C8: 4 | O8: =B8+C8+D8+E8+F8+G8+H8+I8+J8+K8+L8 -> 8 | P8: =O8/$O$13 -> 0.14545455
A9: João | B9: 7 | C9: 2 | O9: =B9+C9+D9+E9+F9+G9+H9+I9+J9+K9+L9 -> 9 | P9: =O9/$O$13 -> 0.16363636
A10: Ana | B10: 2 | C10: 1 | F10: 1 | O10: =B10+C10+D10+E10+F10+G10+H10+I10+J10+K10+L10 -> 4 | P10: =O10/$O$13 -> 0.072727273
A11: Jéssica Rosa | B11: 6 | D11: 1 | O11: =B11+C11+D11+E11+F11+G11+H11+I11+J11+K11+L11 -> 7 | P11: =O11/$O$13 -> 0.12727273
A12: Diego | O12: =B12+C12+D12+E12+F12+G12+H12+I12+J12+K12+L12 -> 0 | P12: =O12/$O$13 -> 0
A13: Total | B13: =SUM(B3:B12) -> 40 | C13: =SUM(C3:C12) -> 13 | D13: =SUM(D3:D12) -> 1 | E13: =SUM(E3:E12) -> 0 | F13: =SUM(F3:F12) -> 1 | G13: =SUM(G3:G12) -> 0 | H13: =SUM(H3:H12) -> 0 | I13: =SUM(I3:I12) -> 0 | ... O13: =SUM(O3:O12) -> 55 | P13: =SUM(P2:P12) -> 1
A16: Produto | B16: Contador | C16: Corretor | D16: Médico | E16: Dentista | F16: RCPM | G16: Advogado | H16: Despachante | I16: Posto | J16: Cartório | K16: D & O | L16: Turismo | M16: Diversos
A17: Total | B17: =B46 -> 11 | C17: =C46 -> 8 | D17: =D46 -> 19 | E17: =E46 -> 3 | F17: =F46 -> 0 | G17: =G46 -> 1 | H17: =H46 -> 0 | I17: =I46 -> 1 | ... M17: =M46 -> 5
A18: Estado
A19: AC
A20: AL
A21: AM
A22: AP
A23: BA | C23: 1
A24: CE | B24: 1
A25: DF | B25: 1
A26: ES | C26: 1
A27: GO
A28: MA
A29: MG
A30: MS | B30: 1 | D30: 1 | L30: 1
A31: MT
A32: PA
A33: PB
A34: PE
A35: PI
A36: PR | C36: 1 | E36: 1
A37: RJ | D37: 5 | J37: 1 | L37: 1
A38: RN
A39: RO | G39: 1
A40: RR
A41: RS | B41: 1 | M41: 1
A42: SC | B42: 1 | D42: 2 | M42: 1
...

Sheet Julho 2019
A1: ACIONAMENTO - MAIO
A2: Regulador/Seguradora | B2: Argo | C2: AIG | D2: AXA | E2: CHUBB | F2: QBE | G2: FATOR | O2: Total
A3: Carlos | B3: 6 | C3: 1 | O3: =B3+C3+D3+E3+F3+G3+H3+I3+J3+K3+L3 -> 7 | P3: =O3/$O$13 -> 0.1147541
A4: Carol | B4: 7 | C4: 2 | O4: =B4+C4+D4+E4+F4+G4+H4+I4+J4+K4+L4 -> 9 | P4: =O4/$O$13 -> 0.14754098
A5: Everton | B5: 2 | O5: =B5+C5+D5+E5+F5+G5+H5+I5+J5+K5+L5 -> 2 | P5: =O5/$O$13 -> 0.032786885
A6: Karisa | B6: 7 | C6: 1 | D6: 1 | O6: =B6+C6+D6+E6+F6+G6+H6+I6+J6+K6+L6 -> 9 | P6: =O6/$O$13 -> 0.14754098
A7: Seidy | B7: 8 | C7: 1 | O7: =B7+C7+D7+E7+F7+G7+H7+I7+J7+K7+L7 -> 9 | P7: =O7/$O$13 -> 0.14754098
A8: Teresa | B8: 6 | C8: 2 | E8: 1 | O8: =B8+C8+D8+E8+F8+G8+H8+I8+J8+K8+L8 -> 9 | P8: =O8/$O$13 -> 0.14754098
A9: João | B9: 5 | O9: =B9+C9+D9+E9+F9+G9+H9+I9+J9+K9+L9 -> 5 | P9: =O9/$O$13 -> 0.081967213
A10: Ana | O10: =B10+C10+D10+E10+F10+G10+H10+I10+J10+K10+L10 -> 0 | P10: =O10/$O$13 -> 0
A11: Jéssica Rosa | B11: 8 | E11: 1 | O11: =B11+C11+D11+E11+F11+G11+H11+I11+J11+K11+L11 -> 9 | P11: =O11/$O$13 -> 0.14754098
A12: Diego | B12: 1 | C12: 1 | O12: =B12+C12+D12+E12+F12+G12+H12+I12+J12+K12+L12 -> 2 | P12: =O12/$O$13 -> 0.032786885
A13: Total | B13: =SUM(B3:B12) -> 50 | C13: =SUM(C3:C12) -> 8 | D13: =SUM(D3:D12) -> 1 | E13: =SUM(E3:E12) -> 2 | F13: =SUM(F3:F12) -> 0 | G13: =SUM(G3:G12) -> 0 | H13: =SUM(H3:H12) -> 0 | I13: =SUM(I3:I12) -> 0 | ... O13: =SUM(O3:O12) -> 61 | P13: =SUM(P2:P12) -> 1
A16: Produto | B16: Contador | C16: Corretor | D16: Médico | E16: Dentista | F16: RCPM | G16: Advogado | H16: Despachante | I16: Posto | J16: Cartório | K16: D & O | L16: Turismo | M16: Diversos
A17: Total | B17: =B46 -> 8 | C17: =C46 -> 12 | D17: =D46 -> 20 | E17: =E46 -> 8 | F17: =F46 -> 0 | G17: =G46 -> 0 | H17: =H46 -> 0 | I17: =I46 -> 2 | ... M17: =M46 -> 9
A18: Estado
A19: AC
A20: AL
A21: AM
A22: AP
A23: BA
A24: CE
A25: DF | C25: 1
A26: ES
A27: GO
A28: MA | M28: 1
A29: MG | C29: 2
A30: MS | D30: 1
A31: MT
A32: PA
A33: PB
A34: PE
A35: PI
A36: PR | C36: 2 | E36: 2
A37: RJ | B37: 2 | D37: 7 | E37: 3
A38: RN
A39: RO | E39: 1
A40: RR
A41: RS | D41: 1
A42: SC | C42: 1 | D42: 5 | E42: 1 | M42: 2
...

Sheet Agosto 2019
A1: ACIONAMENTO - MAIO
A2: Regulador/Seguradora | B2: Argo | C2: AIG | D2: AXA | E2: CHUBB | F2: QBE | G2: FATOR | O2: Total
A3: Carlos | B3: 8 | C3: 5 | O3: =B3+C3+D3+E3+F3+G3+H3+I3+J3+K3+L3 -> 13 | P3: =O3/$O$12 -> 0.14130435
A4: Carol | B4: 4 | C4: 9 | O4: =B4+C4+D4+E4+F4+G4+H4+I4+J4+K4+L4 -> 13 | P4: =O4/$O$12 -> 0.14130435
A5: Everton | B5: 4 | O5: =B5+C5+D5+E5+F5+G5+H5+I5+J5+K5+L5 -> 4 | P5: =O5/$O$12 -> 0.043478261
A6: Karisa | B6: 8 | C6: 1 | O6: =B6+C6+D6+E6+F6+G6+H6+I6+J6+K6+L6 -> 9 | P6: =O6/$O$12 -> 0.097826087
A7: Seidy | B7: 8 | C7: 3 | D7: 1 | O7: =B7+C7+D7+E7+F7+G7+H7+I7+J7+K7+L7 -> 12 | P7: =O7/$O$12 -> 0.13043478
A8: Teresa | B8: 8 | C8: 5 | D8: 1 | O8: =B8+C8+D8+E8+F8+G8+H8+I8+J8+K8+L8 -> 14 | P8: =O8/$O$12 -> 0.15217391
A9: João | B9: 5 | C9: 3 | O9: =B9+C9+D9+E9+F9+G9+H9+I9+J9+K9+L9 -> 8 | P9: =O9/$O$12 -> 0.086956522
A10: Jéssica Rosa | B10: 6 | C10: 2 | D10: 2 | O10: =B10+C10+D10+E10+F10+G10+H10+I10+J10+K10+L10 -> 10 | P10: =O10/$O$12 -> 0.10869565
A11: Diego | B11: 6 | C11: 3 | O11: =B11+C11+D11+E11+F11+G11+H11+I11+J11+K11+L11 -> 9 | P11: =O11/$O$12 -> 0.097826087
A12: Total | B12: =SUM(B3:B11) -> 57 | C12: =SUM(C3:C11) -> 31 | D12: =SUM(D3:D11) -> 4 | E12: =SUM(E3:E11) -> 0 | F12: =SUM(F3:F11) -> 0 | G12: =SUM(G3:G11) -> 0 | H12: =SUM(H3:H11) -> 0 | I12: =SUM(I3:I11) -> 0 | ... O12: =SUM(O3:O11) -> 92 | P12: =SUM(P2:P11) -> 1
A15: Produto | B15: Contador | C15: Corretor | D15: Médico | E15: Dentista | F15: RCPM | G15: Advogado | H15: Despachante | I15: Posto | J15: Cartório | K15: D & O | L15: Turismo | M15: Diversos
A16: Total | B16: =B45 -> 29 | C16: =C45 -> 20 | D16: =D45 -> 20 | E16: =E45 -> 3 | F16: =F45 -> 0 | G16: =G45 -> 5 | H16: =H45 -> 0 | I16: =I45 -> 0 | ... M16: =M45 -> 9
A17: Estado
A18: AC
A19: AL
A20: AM | B20: 1
A21: AP
A22: BA
A23: CE
A24: DF | B24: 1
A25: ES
A26: GO | C26: 1 | L26: 1 | M26: 2
A27: MA
A28: MG | B28: 2 | L28: 1 | M28: 1
A29: MS | D29: 2 | E29: 1
A30: MT | B30: 3
A31: PA
A32: PB
A33: PE | B33: 1
A34: PI
A35: PR | B35: 1 | C35: 3 | D35: 1 | J35: 1
A36: RJ | B36: 2 | C36: 3 | D36: 5 | E36: 1 | G36: 1 | M36: 2
A37: RN
A38: RO
A39: RR
A40: RS | B40: 7 | D40: 1 | E40: 1
A41: SC | C41: 1 | D41: 4 | G41: 2
A42: SE | B42: 1 | C42: 1 | D42: 1
...

Sheet Setembro 2019
A4: ACIONAMENTO - MAIO
A5: Regulador/Seguradora | B5: Argo | C5: AIG | D5: AXA | E5: CHUBB | F5: QBE | G5: FATOR | O5: Total
A6: Carlos | B6: 10 | C6: 2 | D6: 1 | O6: =B6+C6+D6+E6+F6+G6+H6+I6+J6+K6+L6 -> 13 | P6: =O6/$O$12 -> 1.4444444
A7: Carol | B7: 5 | C7: 2 | O7: =B7+C7+D7+E7+F7+G7+H7+I7+J7+K7+L7 -> 7 | P7: =O7/$O$12 -> 0.77777778
A8: Everton | B8: 7 | C8: 1 | D8: 1 | O8: =B8+C8+D8+E8+F8+G8+H8+I8+J8+K8+L8 -> 9 | P8: =O8/$O$12 -> 1
A9: Karisa | B9: 3 | C9: 3 | D9: 1 | O9: =B9+C9+D9+E9+F9+G9+H9+I9+J9+K9+L9 -> 7 | P9: =O9/$O$12 -> 0.77777778
A10: Seidy | B10: 6 | C10: 1 | G10: 2 | O10: =B10+C10+D10+E10+F10+G10+H10+I10+J10+K10+L10 -> 9 | P10: =O10/$O$12 -> 1
A11: Teresa | B11: 4 | C11: 3 | D11: 1 | O11: =B11+C11+D11+E11+F11+G11+H11+I11+J11+K11+L11 -> 8 | P11: =O11/$O$12 -> 0.88888889
A12: João | B12: 7 | C12: 2 | O12: =B12+C12+D12+E12+F12+G12+H12+I12+J12+K12+L12 -> 9 | P12: =O12/$O$12 -> 1
A13: Jéssica Rosa | B13: 5 | C13: 1 | F13: 1 | O13: =B13+C13+D13+E13+F13+G13+H13+I13+J13+K13+L13 -> 7 | P13: =O13/$O$12 -> 0.77777778
A14: Diego | B14: 5 | C14: 2 | O14: =B14+C14+D14+E14+F14+G14+H14+I14+J14+K14+L14 -> 7 | P14: =O14/$O$12 -> 0.77777778
A15: Total | B15: =SUM(B6:B14) -> 52 | C15: =SUM(C6:C14) -> 17 | D15: =SUM(D6:D14) -> 4 | E15: =SUM(E6:E14) -> 0 | F15: =SUM(F6:F14) -> 1 | G15: =SUM(G6:G14) -> 2 | H15: =SUM(H6:H14) -> 0 | I15: =SUM(I6:I14) -> 0 | ... O15: =SUM(O6:O14) -> 76 | P15: =SUM(P5:P14) -> 8.4444444
A18: Produto | B18: Contador | C18: Corretor | D18: Médico | E18: Dentista | F18: RCPM | G18: Advogado | H18: Despachante | I18: Posto | J18: Cartório | K18: D & O | L18: Turismo | M18: Diversos
A19: Total | B19: =B48 -> 12 | C19: =C48 -> 16 | D19: =D48 -> 23 | E19: =E48 -> 6 | F19: =F48 -> 0 | G19: =G48 -> 0 | H19: =H48 -> 3 | I19: =I48 -> 1 | ... M19: =M48 -> 8
A20: Estado
A21: AC
A22: AL
A23: AM
A24: AP
A25: BA
A26: CE | J26: 1
A27: DF | D27: 1 | M27: 1
A28: ES | L28: 2
A29: GO | D29: 2
A30: MA
A31: MG | B31: 2 | C31: 1 | D31: 1
A32: MS | C32: 2 | D32: 4
A33: MT | D33: 1 | E33: 1
A34: PA
A35: PB | D35: 1
A36: PE
A37: PI
A38: PR | B38: 1 | C38: 2 | E38: 5 | L38: 1
A39: RJ | C39: 1 | D39: 4
A40: RN
A41: RO | C41: 1 | D41: 1
A42: RR
A43: RS | B43: 2 | M43: 1
A44: SC | B44: 1 | D44: 2 | L44: 1
A45: SE
...

Sheet Outubro 2019
A1: ACIONAMENTO - MAIO
A2: Regulador/Seguradora | B2: Argo | C2: AIG | D2: AXA | E2: CHUBB | F2: QBE | G2: FATOR | O2: Total
A3: Carlos | B3: 10 | C3: 1 | D3: 1 | O3: =B3+C3+D3+E3+F3+G3+H3+I3+J3+K3+L3 -> 12 | P3: =O3/$O$12 -> 0.13793103
A4: Carol | B4: 7 | C4: 4 | O4: =B4+C4+D4+E4+F4+G4+H4+I4+J4+K4+L4 -> 11 | P4: =O4/$O$12 -> 0.12643678
A5: Everton | B5: 13 | O5: =B5+C5+D5+E5+F5+G5+H5+I5+J5+K5+L5 -> 13 | P5: =O5/$O$12 -> 0.14942529
A6: Karisa | B6: 5 | D6: 1 | O6: =B6+C6+D6+E6+F6+G6+H6+I6+J6+K6+L6 -> 6 | P6: =O6/$O$12 -> 0.068965517
A7: Seidy | B7: 10 | C7: 4 | O7: =B7+C7+D7+E7+F7+G7+H7+I7+J7+K7+L7 -> 14 | P7: =O7/$O$12 -> 0.16091954
A8: Teresa | B8: 11 | C8: 1 | O8: =B8+C8+D8+E8+F8+G8+H8+I8+J8+K8+L8 -> 12 | P8: =O8/$O$12 -> 0.13793103
A9: João | B9: 7 | C9: 2 | O9: =B9+C9+D9+E9+F9+G9+H9+I9+J9+K9+L9 -> 9 | P9: =O9/$O$12 -> 0.10344828
A10: Jéssica Rosa | B10: 3 | C10: 4 | F10: 1 | O10: =B10+C10+D10+E10+F10+G10+H10+I10+J10+K10+L10 -> 8 | P10: =O10/$O$12 -> 0.091954023
A11: Diego | B11: 1 | C11: 1 | O11: =B11+C11+D11+E11+F11+G11+H11+I11+J11+K11+L11 -> 2 | P11: =O11/$O$12 -> 0.022988506
A12: Total | B12: =SUM(B3:B11) -> 67 | C12: =SUM(C3:C11) -> 17 | D12: =SUM(D3:D11) -> 2 | E12: =SUM(E3:E11) -> 0 | F12: =SUM(F3:F11) -> 1 | G12: =SUM(G3:G11) -> 0 | H12: =SUM(H3:H11) -> 0 | I12: =SUM(I3:I11) -> 0 | ... O12: =SUM(O3:O11) -> 87 | P12: =SUM(P2:P11) -> 1
A15: Produto | B15: Contador | C15: Corretor | D15: Médico | E15: Dentista | F15: RCPM | G15: Advogado | H15: Despachante | I15: Posto | J15: Cartório | K15: D & O | L15: Turismo | M15: Diversos
A16: Total | B16: =B45 -> 17 | C16: =C45 -> 15 | D16: =D45 -> 20 | E16: =E45 -> 10 | F16: =F45 -> 0 | G16: =G45 -> 0 | H16: =H45 -> 0 | I16: =I45 -> 2 | ... M16: =M45 -> 18
A17: Estado
A18: AC
A19: AL
A20: AM
A21: AP
A22: BA | D22: 1
A23: CE
A24: DF | B24: 1 | M24: 1
A25: ES
A26: GO | D26: 1 | E26: 2 | M26: 1
A27: MA
A28: MG | M28: 1
A29: MS | B29: 1 | D29: 3 | E29: 1
A30: MT | B30: 3 | C30: 1 | D30: 1
A31: PA
A32: PB | B32: 1
A33: PE
A34: PI | E34: 1
A35: PR | C35: 3 | D35: 3 | E35: 1 | L35: 1 | M35: 2
A36: RJ | C36: 1 | D36: 2 | M36: 3
A37: RN
A38: RO
A39: RR
A40: RS | B40: 1 | D40: 1 | L40: 1 | M40: 1
A41: SC | B41: 2 | D41: 1 | M41: 1
A42: SE | B42: 1
...

Sheet Novembro 2019
A1: ACIONAMENTO - MAIO
A2: Regulador/Seguradora | B2: Argo | C2: AIG | D2: AXA | E2: CHUBB | F2: QBE | G2: FATOR | H2: Porto Seguro | I2: FAIRFAX | O2: Total
A3: Carlos | B3: 6 | O3: =B3+C3+D3+E3+F3+G3+H3+I3+J3+K3+L3 -> 6 | P3: =O3/$O$12 -> 0.095238095
A4: Carol | B4: 6 | C4: 2 | O4: =B4+C4+D4+E4+F4+G4+H4+I4+J4+K4+L4 -> 8 | P4: =O4/$O$12 -> 0.12698413
A5: Everton | B5: 8 | O5: =B5+C5+D5+E5+F5+G5+H5+I5+J5+K5+L5 -> 8 | P5: =O5/$O$12 -> 0.12698413
A6: Karisa | B6: 6 | O6: =B6+C6+D6+E6+F6+G6+H6+I6+J6+K6+L6 -> 6 | P6: =O6/$O$12 -> 0.095238095
A7: Seidy | B7: 8 | O7: =B7+C7+D7+E7+F7+G7+H7+I7+J7+K7+L7 -> 8 | P7: =O7/$O$12 -> 0.12698413
A8: Teresa | B8: 5 | C8: 1 | G8: 1 | O8: =B8+C8+D8+E8+F8+G8+H8+I8+J8+K8+L8 -> 7 | P8: =O8/$O$12 -> 0.11111111
A9: João | B9: 6 | C9: 3 | I9: 1 | O9: =B9+C9+D9+E9+F9+G9+H9+I9+J9+K9+L9 -> 10 | P9: =O9/$O$12 -> 0.15873016
A10: Jéssica Rosa | B10: 5 | C10: 1 | G10: 1 | O10: =B10+C10+D10+E10+F10+G10+H10+I10+J10+K10+L10 -> 7 | P10: =O10/$O$12 -> 0.11111111
A11: Diego | B11: 1 | G11: 1 | H11: 1 | O11: =B11+C11+D11+E11+F11+G11+H11+I11+J11+K11+L11 -> 3 | P11: =O11/$O$12 -> 0.047619048
A12: Total | B12: =SUM(B3:B11) -> 51 | C12: =SUM(C3:C11) -> 7 | D12: =SUM(D3:D11) -> 0 | E12: =SUM(E3:E11) -> 0 | F12: =SUM(F3:F11) -> 0 | G12: =SUM(G3:G11) -> 3 | H12: =SUM(H3:H11) -> 1 | I12: =SUM(I3:I11) -> 1 | ... O12: =SUM(O3:O11) -> 63 | P12: =SUM(P2:P11) -> 1
A15: Produto | B15: Contador | C15: Corretor | D15: Médico | E15: Dentista | F15: RCPM | G15: Advogado | H15: Despachante | I15: Posto | J15: Cartório | K15: D & O | L15: Turismo | M15: Diversos
A16: Total | B16: =B45 -> 10 | C16: =C45 -> 9 | D16: =D45 -> 20 | E16: =E45 -> 6 | F16: =F45 -> 0 | G16: =G45 -> 2 | H16: =H45 -> 1 | I16: =I45 -> 1 | ... M16: =M45 -> 12
A17: Estado
A18: AC
A19: AL
A20: AM
A21: AP
A22: BA | B22: 1 | M22: 1
A23: CE
A24: DF
A25: ES
A26: GO
A27: MA
A28: MG | B28: 2 | C28: 1 | L28: 1 | M28: 2
A29: MS | D29: 2 | E29: 1
A30: MT | C30: 1
A31: PA
A32: PB
A33: PE | C33: 1
A34: PI
A35: PR | B35: 2 | C35: 1 | D35: 2 | H35: 1
A36: RJ | B36: 1 | D36: 7 | E36: 1 | M36: 4
A37: RN
A38: RO | D38: 1 | G38: 1 | M38: 1
A39: RR
A40: RS | B40: 1 | C40: 1 | L40: 1
A41: SC | C41: 1 | D41: 3 | E41: 2 | M41: 1
A42: SE
...

Sheet Dezembro 2019
A1: ACIONAMENTO - MAIO
A2: Regulador/Seguradora | B2: Argo | C2: AIG | D2: AXA | E2: CHUBB | F2: QBE | G2: FATOR | H2: Porto Seguro | I2: FAIRFAX | J2: ZURICH | O2: Total
A3: Carlos | B3: 3 | G3: 1 | J3: 1 | O3: =B3+C3+D3+E3+F3+G3+H3+I3+J3+K3+L3 -> 5 | P3: =O3/$O$12 -> 0.11363636
A4: Carol | B4: 4 | F4: 1 | O4: =B4+C4+D4+E4+F4+G4+H4+I4+J4+K4+L4 -> 5 | P4: =O4/$O$12 -> 0.11363636
A5: Everton | B5: 5 | O5: =B5+C5+D5+E5+F5+G5+H5+I5+J5+K5+L5 -> 5 | P5: =O5/$O$12 -> 0.11363636
A6: Karisa | B6: 6 | H6: 1 | O6: =B6+C6+D6+E6+F6+G6+H6+I6+J6+K6+L6 -> 7 | P6: =O6/$O$12 -> 0.15909091
A7: Seidy | B7: 5 | O7: =B7+C7+D7+E7+F7+G7+H7+I7+J7+K7+L7 -> 5 | P7: =O7/$O$12 -> 0.11363636
A8: Teresa | B8: 2 | O8: =B8+C8+D8+E8+F8+G8+H8+I8+J8+K8+L8 -> 2 | P8: =O8/$O$12 -> 0.045454545
A9: João | B9: 6 | O9: =B9+C9+D9+E9+F9+G9+H9+I9+J9+K9+L9 -> 6 | P9: =O9/$O$12 -> 0.13636364
A10: Jéssica Rosa | B10: 6 | O10: =B10+C10+D10+E10+F10+G10+H10+I10+J10+K10+L10 -> 6 | P10: =O10/$O$12 -> 0.13636364
A11: Diego | B11: 1 | H11: 2 | O11: =B11+C11+D11+E11+F11+G11+H11+I11+J11+K11+L11 -> 3 | P11: =O11/$O$12 -> 0.068181818
A12: Total | B12: =SUM(B3:B11) -> 38 | C12: =SUM(C3:C11) -> 0 | D12: =SUM(D3:D11) -> 0 | E12: =SUM(E3:E11) -> 0 | F12: =SUM(F3:F11) -> 1 | G12: =SUM(G3:G11) -> 1 | H12: =SUM(H3:H11) -> 3 | I12: =SUM(I3:I11) -> 0 | ... O12: =SUM(O3:O11) -> 44 | P12: =SUM(P2:P11) -> 1
A15: Produto | B15: Contador | C15: Corretor | D15: Médico | E15: Dentista | F15: RCPM | G15: Advogado | H15: ECV Vistoria Veicular | I15: Posto | J15: Cartório | K15: D & O | L15: Turismo | M15: Diversos
A16: Total | B16: =B45 -> 10 | C16: =C45 -> 4 | D16: =D45 -> 17 | E16: =E45 -> 4 | F16: =F45 -> 0 | G16: =G45 -> 1 | H16: =H45 -> 1 | I16: =I45 -> 0 | ... M16: =M45 -> 3
A17: Estado
A18: AC
A19: AL
A20: AM | B20: 1
A21: AP
A22: BA | D22: 1
A23: CE
A24: DF
A25: ES
A26: GO
A27: MA
A28: MG | B28: 2 | M28: 1
A29: MS | D29: 4
A30: MT
A31: PA | B31: 1
A32: PB
A33: PE | B33: 1
A34: PI
A35: PR | D35: 2
A36: RJ | D36: 5 | E36: 1
A37: RN | L37: 1
A38: RO | D38: 1
A39: RR
A40: RS | D40: 1 | M40: 1
A41: SC | B41: 1 | E41: 1
A42: SE
...

Sheet Resumo Estado e Ramo
A1: Estado | B1: 2012 | C1: 2013 | D1: 2014 | E1: 2015 | F1: 2016 | G1: 2017 | H1: 2018
A2: AC | D2: 1
A3: AL | E3: 1 | F3: 2 | G3: 3
A4: AM | C4: 2 | D4: 4 | E4: 1 | F4: 6
A5: BA | D5: 6 | E5: 5 | F5: 18 | G5: 13
A6: CE | D6: 2 | E6: 2 | F6: 12 | G6: 9
A7: DF | C7: 1 | D7: 2 | E7: 43 | F7: 48 | G7: 8
A8: ES | B8: 1 | D8: 5 | E8: 14 | F8: 20 | G8: 18
A9: GO | D9: 5 | E9: 11 | F9: 19 | G9: 21
A10: MA | E10: 1 | F10: 3
A11: MG | C11: 1 | D11: 10 | E11: 37 | F11: 83 | G11: 49
A12: MS | D12: 2 | E12: 13 | F12: 18 | G12: 11
A13: MT | D13: 5 | E13: 8 | F13: 14 | G13: 11
